Workbook

Sheet params
A1: Table 1: Summary Output (AR1) | I1: variable | J1: X2.5 | K1: X50 | L1: X97.5 | M1: post_cv | T1: Table 2: Summary Output (Ricker) | AB1: variable | AC1: X2.5 | AD1: X50 | AE1: X97.5 | AF1: post_cv
I2: lnalpha | J2: 1.236711 | K2: 1.5848411 | L2: 1.9088989 | M2: 0.10644444 | T2: Parameter | U2: 0.025 | V2: Median | W2: 0.975 | X2: Posterior CV | AB2: lnalpha | AC2: 1.2839696 | AD2: 1.5933278 | AE2: 1.8967487 | AF2: 0.097671437
A3: Parameter | B3: 0.025 | C3: Median | D3: 0.975 | E3: Posterior CV | I3: lnalpha.c | J3: 1.3372744 | K3: 1.6740486 | L3: 2.0083767 | M3: 0.10177034 | T3: ln(a) | U3: =AC2 -> 1.2839696 | V3: =AD2 -> 1.5933278 | W3: =AE2 -> 1.8967487 | X3: =AF2 -> 0.097671437 | AB3: lnalpha.c | AC3: 1.3732153 | AD3: 1.6743534 | AE3: 1.9883288 | AF3: 0.09346165
A4: ln(a) | B4: =J2 -> 1.236711 | C4: =K2 -> 1.5848411 | D4: =L2 -> 1.9088989 | E4: =M2 -> 0.10644444 | I4: beta | J4: 0.094269282 | K4: 0.13384214 | L4: 0.17113835 | M4: 0.14641497 | T4: ln(a)' | U4: =AC3 -> 1.3732153 | V4: =AD3 -> 1.6743534 | W4: =AE3 -> 1.9883288 | X4: =AF3 -> 0.09346165 | AB4: beta | AC4: 0.098619178 | AD4: 0.13539227 | AE4: 0.17175209 | AF4: 0.13710612
A5: ln(a)' | B5: =J3 -> 1.3372744 | C5: =K3 -> 1.6740486 | D5: =L3 -> 2.0083767 | E5: =M3 -> 0.10177034 | I5: beta1 | J5: 9.42692820554085e-06 | K5: 1.33842144022435e-05 | L5: 1.71138345114143e-05 | M5: 0.14641497 | T5: b | U5: 9.86 x 10-6 | V5: 1.35 x 10-5 | W5: 1.72 x 10-5 | X5: =AF5 -> 0.13710612 | AB5: beta1 | AC5: 9.86191775922459e-06 | AD5: 1.35392270127364e-05 | AE5: 1.71752090840204e-05 | AF5: 0.13710612
A6: b | B6: 9.43 x 10-6 | C6: 1.34 x 10-5 | D6: 1.714 x 10-5 | E6: =M5 -> 0.14641497 | I6: alpha | J6: 3.4442667 | K6: 4.8785162 | L6: 6.7456569 | M6: 0.16837463 | T6: a | U6: =AC6 -> 3.6109454 | V6: =AD6 -> 4.9200948 | W6: =AE6 -> 6.6641919 | X6: =AF6 -> 0.15653197 | AB6: alpha | AC6: 3.6109454 | AD6: 4.9200948 | AE6: 6.6641919 | AF6: 0.15653197
A7: a | B7: =J6 -> 3.4442667 | C7: =K6 -> 4.8785162 | D7: =L6 -> 6.7456569 | E7: =M6 -> 0.16837463 | I7: alpha.c | J7: 3.8086487 | K7: 5.333718 | L7: 7.4512117 | M7: 0.17661029 | T7: a' | U7: =AC7 -> 3.9480246 | V7: =AD7 -> 5.3353441 | W7: =AE7 -> 7.3033184 | X7: =AF7 -> 0.1585245 | AB7: alpha.c | AC7: 3.9480246 | AD7: 5.3353441 | AE7: 7.3033184 | AF7: 0.1585245
A8: a' | B8: =J7 -> 3.8086487 | C8: =K7 -> 5.333718 | D8: =L7 -> 7.4512117 | E8: =M7 -> 0.17661029 | I8: Smsy_lambert | J8: 39954.646 | K8: 46158.087 | L8: 56888.647 | M8: 0.092081637 | T8: sR | U8: =AF72 -> 0.32759348 | V8: =AG72 -> 0.40174414 | W8: =AH72 -> 0.50427075 | X8: =AK72 -> 0.11208191 | AB8: Smsy_lambert | AC8: 40036.966 | AD8: 45859.581 | AE8: 54876.721 | AF8: 0.083221261
A9: f | B9: =M71 -> -0.23005101 | C9: =N71 -> 0.097634603 | D9: =O71 -> 0.45580217 | E9: =R71 -> 1.7521148 | I9: Smsy_lambert.c | J9: 41275.452 | K9: 47923.849 | L9: 60103.639 | M9: 0.098941923 | T9: SMSY(Lambert W)) | U9: =AC8 -> 40036.966 | V9: =AD8 -> 45859.581 | W9: =AE8 -> 54876.721 | X9: =AF8 -> 0.083221261 | AB9: Smsy_lambert.c | AC9: 41271.455 | AD9: 47445.299 | AE9: 57800.516 | AF9: 0.088573536
A10: sR | B10: =M72 -> 0.33083231 | C10: =N72 -> 0.40617203 | D10: =O72 -> 0.5183989 | E10: =R72 -> 0.11623349 | I10: Umsy_lambert | J10: 0.51438071 | K10: 0.61924416 | L10: 0.70113513 | M10: 0.076088629 | T10: UMSY(Lambert W) | U10: =AC10 -> 0.52966326 | V10: =AD10 -> 0.62157923 | W10: =AE10 -> 0.69832933 | X10: =AF10 -> 0.069150387 | AB10: Umsy_lambert | AC10: 0.52966326 | AD10: 0.62157923 | AE10: 0.69832933 | AF10: 0.069150387
A11: SMSY(Lambert W)) | B11: =J8 -> 39954.646 | C11: =K8 -> 46158.087 | D11: =L8 -> 56888.647 | E11: =M8 -> 0.092081637 | I11: Umsy_lambert.c | J11: 0.5465045 | K11: 0.64327065 | L11: 0.72335532 | M11: 0.069889888 | T11: SMAX | U11: =AC12 -> 58223.454 | V11: =AD12 -> 73859.46 | W11: =AE12 -> 101400.16 | X11: =AF12 -> 0.14711136 | AB11: Umsy_lambert.c | AC11: 0.55762284 | AD11: 0.64335079 | AE11: 0.71898425 | AF11: 0.064103917
A12: UMSY(Lambert W) | B12: =J10 -> 0.51438071 | C12: =K10 -> 0.61924416 | D12: =L10 -> 0.70113513 | E12: =M10 -> 0.076088629 | I12: Smax | J12: 58432.258 | K12: 74714.882 | L12: 106079.11 | M12: 0.16048557 | T12: SEQ | U12: =AC15 -> 105989.09 | V12: =AD15 -> 117694.08 | W12: =AE15 -> 135893.92 | X12: =AF15 -> 0.064835452 | AB12: Smax | AC12: 58223.454 | AD12: 73859.46 | AE12: 101400.16 | AF12: 0.14711136
A13: SMAX | B13: =J12 -> 58432.258 | C13: =K12 -> 74714.882 | D13: =L12 -> 106079.11 | E13: =M12 -> 0.16048557 | I13: Rmsy.c | J13: 114078.88 | K13: 135405.65 | L13: 166480.61 | M13: 0.10812199 | T13: MSY | U13: =AC16 -> 57262.172 | V13: =AD16 -> 75618.073 | W13: =AE16 -> 97764.8 | X13: =AF16 -> 0.13521431 | AB13: Rmsy.c | AC13: 115640.39 | AD13: 134128.39 | AE13: 157970.85 | AF13: 0.079815383
A14: SEQ | B14: =J15 -> 105370.34 | C14: =K15 -> 118318.71 | D14: =L15 -> 140496.65 | E14: =M15 -> 0.075324844 | I14: Rmsy | J14: 101750.96 | K14: 122430.19 | L14: 147547.19 | M14: 0.095064688 | AB14: Rmsy | AC14: 104479.85 | AD14: 122097.52 | AE14: 142012.26 | AF14: 0.077969412
A15: MSY | B15: =J16 -> 54497.204 | C15: =K16 -> 75660.093 | D15: =L16 -> 101073.79 | E15: =M16 -> 0.15644832 | I15: Seq | J15: 105370.34 | K15: 118318.71 | L15: 140496.65 | M15: 0.075324844 | V15: =AC24*10^-4 -> 1.3535444e-05 | AB15: Seq | AC15: 105989.09 | AD15: 117694.08 | AE15: 135893.92 | AF15: 0.064835452
I16: MSY | J16: 54497.204 | K16: 75660.093 | L16: 101073.79 | M16: 0.15644832 | AB16: MSY | AC16: 57262.172 | AD16: 75618.073 | AE16: 97764.8 | AF16: 0.13521431
I17: MSYc | J17: 64645.853 | K17: 86716.973 | L17: 117594.57 | M17: 0.16779988 | AB17: MSY.c | AC17: 66516.82 | AD17: 86061.768 | AE17: 111505.27 | AF17: 0.13173892
I18: Rmax.c | J18: 128488.4 | K18: 147562.47 | L18: 179085.86 | M18: 0.094049521 | AB18: Rmax.c | AC18: 129607.86 | AD18: 146260.88 | AE18: 168942.31 | AF18: 0.067479014
I19: Rmax | J19: 117305.54 | K19: 135383.58 | L19: 159144.78 | M19: 0.078810775 | AB19: Rmax | AC19: 119211.4 | AD19: 134786.36 | AE19: 152892.36 | AF19: 0.063403567
I21: variable | J21: Mean | K21: SD | L21: time_series_se | M21: 0.025 | N21: 0.5 | O21: 0.975 | P21: mc_error | Q21: converge | R21: cv | AB21: variable | AC21: Mean | AD21: SD | AE21: time_series_se | AF21: 0.025 | AG21: 0.5 | AH21: 0.975 | AI21: mc_error | AJ21: converge | AK21: cv
I22: Tau | J22: 6.1629444 | K22: 1.3876939 | L22: 0.018086433 | M22: 3.7211044 | N22: 6.061498 | O22: 9.1365905 | P22: 0.013033446 | Q22: TRUE | R22: =K22/J22 -> 0.22516736 | AB22: Tau | AC22: 6.30724 | AD22: 1.3800629 | AE22: 0.017603943 | AF22: 3.9325338 | AG22: 6.19585 | AH22: 9.3181458 | AI22: 0.012755899 | AJ22: TRUE | AK22: =AD22/AC22 -> 0.21880615
I23: alpha | J23: 4.9394869 | K23: 0.83168429 | L23: 0.0104747 | M23: 3.4442667 | N23: 4.8785162 | O23: 6.7456569 | P23: 0.012594562 | Q23: TRUE | R23: =K23/J23 -> 0.16837463 | AB23: alpha | AC23: 4.9772348 | AD23: 0.77909635 | AE23: 0.010187273 | AF23: 3.6109454 | AG23: 4.9200948 | AH23: 6.6641919 | AI23: 0.013075755 | AJ23: TRUE | AK23: =AD23/AC23 -> 0.15653197
I24: beta | J24: 0.13352186 | K24: 0.019549599 | L24: 0.00024918782 | M24: 0.094269282 | N24: 0.13384214 | O24: 0.17113835 | P24: 0.012746442 | Q24: TRUE | R24: =K24/J24 -> 0.14641497 | AB24: beta | AC24: 0.13535444 | AD24: 0.018557922 | AE24: 0.0002408115 | AF24: 0.098619178 | AG24: 0.13539227 | AH24: 0.17175209 | AI24: 0.01297621 | AJ24: TRUE | AK24: =AD24/AC24 -> 0.13710612
I25: e[1] | J25: 0.12005579 | K25: 0.10854373 | L25: 0.0013966575 | M25: -0.10091586 | N25: 0.1231895 | O25: 0.32910489 | P25: 0.012867233 | Q25: TRUE | R25: =K25/J25 -> 0.90411074 | AB25: e[1] | AC25: 0.13187008 | AD25: 0.096293281 | AE25: 0.0012430513 | AF25: -0.055730826 | AG25: 0.13175708 | AH25: 0.3204713 | AI25: 0.012909014 | AJ25: TRUE | AK25: =AD25/AC25 -> 0.73021325
I26: e[2] | J26: 0.56513042 | K26: 0.28306567 | L26: 0.0036448125 | M26: -0.0055793147 | N26: 0.57255752 | O26: 1.1150155 | P26: 0.012876208 | Q26: TRUE | R26: =K26/J26 -> 0.50088557 | AB26: e[2] | AC26: 0.5952049 | AD26: 0.26626421 | AE26: 0.0034368556 | AF26: 0.075918947 | AG26: 0.59528504 | AH26: 1.1159832 | AI26: 0.012907689 | AJ26: TRUE | AK26: =AD26/AC26 -> 0.44734883
I27: e[3] | J27: -0.12971674 | K27: 0.15594163 | L27: 0.0020063883 | M27: -0.44175651 | N27: -0.12450054 | O27: 0.17316952 | P27: 0.012866278 | Q27: TRUE | R27: =K27/J27 -> -1.2021704 | AB27: e[3] | AC27: -0.11242396 | AD27: 0.14345796 | AE27: 0.0018517841 | AF27: -0.39366137 | AG27: -0.11324734 | AH27: 0.16300211 | AI27: 0.0129082 | AJ27: TRUE | AK27: =AD27/AC27 -> -1.2760444
I28: e[4] | J28: -0.32806183 | K28: 0.12629118 | L28: 0.0016250008 | M28: -0.57762952 | N28: -0.32390259 | O28: -0.084145462 | P28: 0.012867096 | Q28: TRUE | R28: =K28/J28 -> -0.38496153 | AB28: e[4] | AC28: -0.3140686 | AD28: 0.11416001 | AE28: 0.0014736452 | AF28: -0.53771474 | AG28: -0.31534227 | AH28: -0.090095015 | AI28: 0.012908593 | AJ28: TRUE | AK28: =AD28/AC28 -> -0.36348751
I29: e[5] | J29: -0.2051721 | K29: 0.083140341 | L29: 0.0010850076 | M29: -0.37635307 | N29: -0.20262955 | O29: -0.048078356 | P29: 0.013050314 | Q29: TRUE | R29: =K29/J29 -> -0.40522245 | AB29: e[5] | AC29: -0.19739943 | AD29: 0.069829238 | AE29: 0.00090151341 | AF29: -0.33534951 | AG29: -0.19801507 | AH29: -0.059988061 | AI29: 0.012910257 | AJ29: TRUE | AK29: =AD29/AC29 -> -0.35374589
I30: e[6] | J30: -0.096743516 | K30: 0.081168937 | L30: 0.0010480183 | M30: -0.2593869 | N30: -0.097162419 | O30: 0.061050247 | P30: 0.012911569 | Q30: TRUE | R30: =K30/J30 -> -0.83901165 | AB30: e[6] | AC30: -0.095047815 | AD30: 0.067614359 | AE30: 0.00087080275 | AF30: -0.22833796 | AG30: -0.095128971 | AH30: 0.03916827 | AI30: 0.012878962 | AJ30: TRUE | AK30: =AD30/AC30 -> -0.71137205
I31: e[7] | J31: 0.12209536 | K31: 0.075517797 | L31: 0.00097504421 | M31: -0.029925913 | N31: 0.12276418 | O31: 0.2692476 | P31: 0.012911449 | Q31: TRUE | R31: =K31/J31 -> 0.61851491 | AB31: e[7] | AC31: 0.12630664 | AD31: 0.061473436 | AE31: 0.00078368067 | AF31: 0.007290376 | AG31: 0.12636584 | AH31: 0.24777673 | AI31: 0.012748282 | AJ31: TRUE | AK31: =AD31/AC31 -> 0.48669996
I32: e[8] | J32: -0.63963393 | K32: 0.079893234 | L32: 0.0010315454 | M32: -0.80143854 | N32: -0.63977017 | O32: -0.48306704 | P32: 0.012911549 | Q32: TRUE | R32: =K32/J32 -> -0.12490462 | AB32: e[8] | AC32: -0.63759535 | AD32: 0.066236376 | AE32: 0.00085190858 | AF32: -0.76774282 | AG32: -0.63764807 | AH32: -0.50554789 | AI32: 0.012861642 | AJ32: TRUE | AK32: =AD32/AC32 -> -0.10388466
I33: e[9] | J33: -0.33318796 | K33: 0.084005889 | L33: 0.0010846512 | M33: -0.49954191 | N33: -0.33387774 | O33: -0.16993602 | P33: 0.012911609 | Q33: TRUE | R33: =K33/J33 -> -0.25212762 | AB33: e[9] | AC33: -0.33214943 | AD33: 0.070658372 | AE33: 0.00091218002 | AF33: -0.47046618 | AG33: -0.33183638 | AH33: -0.19094759 | AI33: 0.012909723 | AJ33: TRUE | AK33: =AD33/AC33 -> -0.21273068
... I74: tauw | J74: 1475.1744 | K74: 45849.595 | L74: 591.97336 | M74: 0.26313313 | N74: 0.99058566 | O74: 326.49819 | P74: 0.012911202 | Q74: TRUE | R74: =K74/J74 -> 31.080796 | AB74: tauw | AC74: 2235.7173 | AD74: 100560.18 | AE74: 1298.2342 | AF74: 0.26069667 | AG74: 1.0127061 | AH74: 438.42465 | AI74: 0.012910022 | AJ74: TRUE | AK74: =AD74/AC74 -> 44.978933

Sheet contrast
A1: year | B1: spawn | C1: recruit25 | D1: recruit50 | E1: recruit75 | F1: ln(R/S) | G1: R/S | H1: contrast | I1: =MAX(B2:B44)/MIN(B2:B44) -> 7.8376452
A2: 1976 | B2: 116989 | C2: 127903.19 | D2: 134724.39 | E2: 137496.32 | F2: =LN(D2/B2) -> 0.14115125 | G2: =(D2/B2) -> 1.1515988
A3: 1977 | B3: 216631 | C3: 97652.74 | D3: 102923.17 | E3: 107616.74 | F3: =LN(D3/B3) -> -0.74421267 | G3: =(D3/B3) -> 0.47510822 | I3: min | J3: =MIN(F2:F44) -> -0.74421267 | L3: min | M3: =MIN(G2:G44) -> 0.47510822
A4: 1978 | B4: 146884 | C4: 83714.564 | D4: 88398.789 | E4: 92490.553 | F4: =LN(D4/B4) -> -0.50778489 | G4: =(D4/B4) -> 0.60182722 | I4: max | J4: =MAX(F2:F44) -> 1.8062853 | L4: max | M4: =MAX(G2:G44) -> 6.0877914
A5: 1979 | B5: 128879 | C5: 77548.378 | D5: 80894.846 | E5: 83093.726 | F5: =LN(D5/B5) -> -0.46572386 | G5: =(D5/B5) -> 0.62768059
A6: 1980 | B6: 94934.708 | C6: 101861.06 | D6: 106015.55 | E6: 108424.68 | F6: =LN(D6/B6) -> 0.11039637 | G6: =(D6/B6) -> 1.1167206
A7: 1981 | B7: 61774 | C7: 115025.09 | D7: 119710.4 | E7: 124395.71 | F7: =LN(D7/B7) -> 0.66159291 | G7: =(D7/B7) -> 1.9378767
A8: 1982 | B8: 75501 | C8: 148451.75 | D8: 151607.09 | E8: 152525.46 | F8: =LN(D8/B8) -> 0.69714632 | G8: =(D8/B8) -> 2.0080143
A9: 1983 | B9: 63645 | C9: 66788.85 | D9: 69898.3 | E9: 71474.89 | F9: =LN(D9/B9) -> 0.093720558 | G9: =(D9/B9) -> 1.0982528
A10: 1984 | B10: 58188 | C10: 88539.298 | D10: 93382.929 | E10: 96349.52 | F10: =LN(D10/B10) -> 0.47302941 | G10: =(D10/B10) -> 1.6048486
A11: 1985 | B11: 107586 | C11: 161113.31 | D11: 170082.11 | E11: 178510.8 | F11: =LN(D11/B11) -> 0.45799082 | G11: =(D11/B11) -> 1.5808945
A12: 1986 | B12: 71543 | C12: 240259.51 | D12: 252681.34 | E12: 262627.11 | F12: =LN(D12/B12) -> 1.2618305 | G12: =(D12/B12) -> 3.5318806
A13: 1987 | B13: 72720 | C13: 191852.29 | D13: 201019.46 | E13: 208353.33 | F13: =LN(D13/B13) -> 1.0167853 | G13: =(D13/B13) -> 2.764294
A14: 1988 | B14: 46166.047 | C14: 125968.63 | D14: 131089.12 | E14: 134611.55 | F14: =LN(D14/B14) -> 1.0436328 | G14: =(D14/B14) -> 2.8395137
A15: 1989 | B15: 83680.441 | C15: 123327.55 | D15: 127588.68 | E15: 130878.48 | F15: =LN(D15/B15) -> 0.4218064 | G15: =(D15/B15) -> 1.5247133
A16: 1990 | B16: 75246.474 | C16: 80574.478 | D16: 83501.13 | E16: 85984.406 | F16: =LN(D16/B16) -> 0.10409112 | G16: =(D16/B16) -> 1.1097016
... A44: 2018 | B44: 27639.807 | C44: 167049.8 | D44: 168265.38 | E44: 169467.7 | F44: =LN(D44/B44) -> 1.8062853 | G44: =(D44/B44) -> 6.0877914
A45: 2019 | B45: 70958.096
A46: 2020 | B46: 64563.269
A47: 2021 | B47: 115592.16
A48: 2022 | B48: 93843.776
A49: 2023 | B49: 138241.33
A50: 2024 | B50: 67895.476

Sheet yield info
A1: AR(1) Model | E1: ENTER DATA HERE FROM R OUTPUT
A2: OY0.9 | B2: 0 | C2: 0 | D2: 0 | E2: 0 | F2: 0 | G2: 0 | H2: 0 | I2: 0 | J2: 0 | K2: 0 | L2: 0 | M2: 0 | N2: 0 | O2: 0 | P2: 0 | Q2: 0 | R2: 0 | S2: 0 | T2: 0 | U2: 0 | V2: 0 | W2: 0 | X2: 0 | Y2: 0 | Z2: 0 | AA2: 0 | AB2: 0 | AC2: 0 | AD2: 0 | AE2: 0 | AF2: 0 | AG2: 0 | AH2: 0 | AI2: 0 | AJ2: 0 | AK2: 0 | AL2: 0 | AM2: 0 | AN2: 0 | AO2: 0 | AP2: 0 | AQ2: 0 | AR2: 0 | AS2: 0 | AT2: 0 | AU2: 0 | AV2: 0 | AW2: 0 | AX2: 0 | AY2: 0 | AZ2: 0 | BA2: 0 | BB2: 0 | BC2: 0 | BD2: 0 | BE2: 0 | BF2: 0 | BG2: 0 | BH2: 0 | BI2: 0 | BJ2: 0 | BK2: 0 | BL2: 0 | BM2: 0 | BN2: 0 | BO2: 0 | BP2: 0 | BQ2: 0 | BR2: 0 | BS2: 0 | BT2: 0 | BU2: 0 | BV2: 0 | BW2: 0 | BX2: 0 | BY2: 0 | BZ2: 0 | CA2: 0 | CB2: 0 | CC2: 0 | CD2: 0 | CE2: 0 | CF2: 0 | CG2: 0 | CH2: 0 | CI2: 0 | CJ2: 0 | CK2: 0 | CL2: 0 | CM2: 0 | CN2: 0 | CO2: 0 | CP2: 0 | CQ2: 0 | CR2: 0 | CS2: 0 | CT2: 0 | CU2: 0 | CV2: 0 | CW2: 0 | CX2: 0 | CY2: 0 | CZ2: 0 | DA2: 0 | DB2: 0 | DC2: 0 | DD2: 0 | DE2: 0 | DF2: 0 | DG2: 0 | DH2: 0 | DI2: 0 | DJ2: 0 | DK2: 0 | DL2: 0 | DM2: 0 | DN2: 0 | DO2: 0 | DP2: 0 | DQ2: 0 | DR2: 0 | DS2: 0 | DT2: 0 | DU2: 0 | DV2: 0 | DW2: 0 | DX2: 0 | DY2: 0 | DZ2: 0 | EA2: 0 | EB2: 0 | EC2: 0 | ED2: 0 | EE2: 0 | EF2: 0 | EG2: 0 | EH2: 0 | EI2: 0 | EJ2: 0 | EK2: 0 | EL2: 0 | EM2: 0 | EN2: 0 | EO2: 0 | EP2: 0 | EQ2: 0 | ER2: 0 | ES2: 0 | ET2: 0 | EU2: 0 | EV2: 0 | EW2: 0 | EX2: 0 | EY2: 0 | EZ2: 0 | FA2: 0 | FB2: 0 | FC2: 0 | FD2: 0 | FE2: 0 | FF2: 0 | FG2: 0 | FH2: 0 | FI2: 0 | FJ2: 0 | FK2: 0 | FL2: 0 | FM2: 0 | FN2: 0 | FO2: 0 | FP2: 0 | FQ2: 0 | FR2: 0 | FS2: 0 | FT2: 0 | FU2: 0 | FV2: 0 | FW2: 0 | FX2: 0 | FY2: 0 | FZ2: 0 | GA2: 0 | GB2: 0 | GC2: 0 | GD2: 0 | GE2: 0 | GF2: 0 | GG2: 0 | GH2: 0 | GI2: 0 | GJ2: 0 | GK2: 0 | GL2: 0 | GM2: 0 | GN2: 0 | GO2: 0 | GP2: 0 | GQ2: 0 | GR2: 0 | GS2: 0 | GT2: 0 | GU2: 0 | GV2: 0 | GW2: 0 | GX2: 0 | GY2: 0 | GZ2: 0 | HA2: 0 | HB2: 0 | HC2: 0 | HD2: 0 | HE2: 0 | HF2: 0 | HG2: 0 | HH2: 0 | HI2: 0 | HJ2: 0 | HK2: 0 | HL2: 0 | HM2: 0 | HN2: 0 | HO2: 0 | HP2: 0 | HQ2: 0 | HR2: 0 | HS2: 0 | HT2: 0 | HU2: 0.00016666667 | HV2: 0.00016666667 | HW2: 0.00033333333 | HX2: 0.00033333333 | HY2: 0.00033333333 | HZ2: 0.00033333333 | IA2: 0.00033333333 | IB2: 5e-04 | IC2: 5e-04 | ID2: 0.00066666667 | IE2: 0.00066666667 | IF2: 0.0011666667 | IG2: 0.0013333333 | IH2: 0.0016666667 | II2: 0.0028333333 | IJ2: 0.0036666667 | IK2: 0.0046666667 | IL2: 0.0055 | IM2: 0.0063333333 | IN2: 0.008 | IO2: 0.0085 | IP2: 0.0091666667 | IQ2: 0.011 | IR2: 0.013 | IS2: 0.0145 | IT2: 0.017666667 | IU2: 0.02 | IV2: 0.022 | IW2: 0.024666667 | IX2: 0.027833333 | IY2: 0.032 | IZ2: 0.034833333 | JA2: 0.040333333 | JB2: 0.044333333 | JC2: 0.0495 | JD2: 0.054833333 | JE2: 0.060833333 | JF2: 0.066333333 | JG2: 0.071833333 | JH2: 0.080333333 | JI2: 0.088166667 | JJ2: 0.096333333 | JK2: 0.1065 | JL2: 0.118 | JM2: 0.12516667 | JN2: 0.13333333 | JO2: 0.14366667 | JP2: 0.1575 | JQ2: 0.169 | JR2: 0.179 | JS2: 0.1895 | JT2: 0.2045 | JU2: 0.21533333 | JV2: 0.23 | JW2: 0.24583333 | JX2: 0.26166667 | JY2: 0.27516667 | JZ2: 0.291 | KA2: 0.3075 | KB2: 0.32483333 | KC2: 0.34216667 | KD2: 0.35833333 | KE2: 0.375 | KF2: 0.392 | KG2: 0.40716667 | KH2: 0.42283333 | KI2: 0.4385 | KJ2: 0.455 | KK2: 0.471 | KL2: 0.48666667 | KM2: 0.50333333 | KN2: 0.51566667 | KO2: 0.53166667 | KP2: 0.54633333 | KQ2: 0.562 | KR2: 0.57316667 | KS2: 0.58666667 | KT2: 0.59966667 | KU2: 0.6145 | KV2: 0.62833333 | KW2: 0.6435 | KX2: 0.65516667 | KY2: 0.668 | KZ2: 0.67983333 | LA2: 0.6935 | LB2: 0.70466667 | LC2: 0.71566667 | LD2: 0.72666667 | LE2: 0.73616667 | LF2: 0.74266667 | LG2: 0.75266667 | LH2: 0.7605 | LI2: 0.77133333 | LJ2: 0.78 | LK2: 0.78733333 | LL2: 0.79716667 | LM2: 0.80483333 | LN2: 0.81116667 | LO2: 0.82083333 | LP2: 0.82933333 | LQ2: 0.83683333 | LR2: 0.84516667 | LS2: 0.8525 | LT2: 0.85883333 | LU2: 0.865 | LV2: 0.87066667 | LW2: 0.87733333 | LX2: 0.88316667 | LY2: 0.88833333 | LZ2: 0.8935 | MA2: 0.897 | MB2: 0.90116667 | MC2: 0.90516667 | MD2: 0.9095 | ME2: 0.91383333 | MF2: 0.918 | MG2: 0.92066667 | MH2: 0.92583333 | MI2: 0.92983333 | MJ2: 0.933 | MK2: 0.93566667 | ML2: 0.93766667 | MM2: 0.93966667 | MN2: 0.943 | MO2: 0.94516667 | MP2: 0.94733333 | MQ2: 0.94883333 | MR2: 0.951 | MS2: 0.95383333 | MT2: 0.9555 | MU2: 0.95733333 | MV2: 0.95916667 | MW2: 0.9605 | MX2: 0.96216667 | MY2: 0.96366667 | MZ2: 0.965 | NA2: 0.96766667 | NB2: 0.969 | NC2: 0.96966667 | ND2: 0.97116667 | NE2: 0.97233333 | NF2: 0.97366667 | NG2: 0.97483333 | NH2: 0.97583333 | NI2: 0.97666667 | NJ2: 0.97883333 | NK2: 0.98 | NL2: 0.9805 | NM2: 0.98183333 | NN2: 0.98266667 | NO2: 0.98316667 | NP2: 0.98383333 | NQ2: 0.98416667 | NR2: 0.98483333 | NS2: 0.9855 | NT2: 0.986 | NU2: 0.9865 | NV2: 0.98683333 | NW2: 0.98783333 | NX2: 0.98833333 | NY2: 0.98866667 | NZ2: 0.98916667 | OA2: 0.9895 | OB2: 0.99 | OC2: 0.9905 | OD2: 0.99116667 | OE2: 0.99183333 | OF2: 0.99216667 | OG2: 0.99216667 | OH2: 0.99233333 | OI2: 0.99233333 | OJ2: 0.99233333 | OK2: 0.9925 | OL2: 0.99266667 | OM2: 0.99316667 | ON2: 0.99333333 | OO2: 0.99366667 | OP2: 0.99366667 | OQ2: 0.99366667 | OR2: 0.99416667 | OS2: 0.99433333 | OT2: 0.99466667 | OU2: 0.995 | OV2: 0.99516667 | OW2: 0.9955 | OX2: 0.9955 | OY2: 0.99566667 | OZ2: 0.99583333 | PA2: 0.99616667 | PB2: 0.99633333 | PC2: 0.9965 | PD2: 0.99666667 | PE2: 0.997 | PF2: 0.99716667 | PG2: 0.99733333 | PH2: 0.99733333 | PI2: 0.99733333 | PJ2: 0.99733333 | PK2: 0.9975 | PL2: 0.9975 | PM2: 0.99783333 | PN2: 0.998 | PO2: 0.99816667 | PP2: 0.9985 | PQ2: 0.9985 | PR2: 0.99866667 | PS2: 0.99866667 | PT2: 0.99883333 | PU2: 0.99883333 | PV2: 0.999 | PW2: 0.99916667 | PX2: 0.99933333 | PY2: 0.99933333 | PZ2: 0.99933333 | QA2: 0.99933333 | QB2: 0.99933333 | QC2: 0.99933333 | QD2: 0.99933333 | QE2: 0.99933333 | QF2: 0.99933333 | QG2: 0.99933333 | QH2: 0.99933333 | QI2: 0.99933333 | QJ2: 0.99933333 | QK2: 0.99933333 | QL2: 0.99933333 | QM2: 0.99933333 | QN2: 0.99933333 | QO2: 0.9995 | QP2: 0.9995 | QQ2: 0.9995 | QR2: 0.9995 | QS2: 0.9995 | QT2: 0.9995 | QU2: 0.9995 | QV2: 0.9995 | QW2: 0.9995 | QX2: 0.9995 | QY2: 0.99966667 | QZ2: 0.99966667 | RA2: 0.99966667 | RB2: 0.99966667 | RC2: 0.99966667 | RD2: 0.99983333 | RE2: 0.99983333 | RF2: 0.99983333 | RG2: 0.99983333 | RH2: 0.99983333 | RI2: 1 | RJ2: 1 | RK2: 1 | RL2: 1 | RM2: 1 | RN2: 1 | RO2: 1 | RP2: 1 | RQ2: 1 | RR2: 1 | RS2: 1 | RT2: 1 | RU2: 1 | RV2: 1 | RW2: 1 | RX2: 1 | RY2: 1 | RZ2: 1 | SA2: 1 | SB2: 1 | SC2: 1 | SD2: 1 | SE2: 1 | SF2: 1 | SG2: 1 | SH2: 1 | SI2: 1 | SJ2: 1 | SK2: 1 | SL2: 1 | SM2: 1 | SN2: 1 | SO2: 1 | SP2: 1 | SQ2: 1 | SR2: 1 | SS2: 1 | ST2: 1 | SU2: 0.99983333 | SV2: 0.99983333 | SW2: 0.99983333 | SX2: 0.99983333 | SY2: 0.99983333 | SZ2: 0.99966667 | TA2: 0.99966667 | TB2: 0.99966667 | TC2: 0.99966667 | TD2: 0.9995 | TE2: 0.9995 | TF2: 0.9995 | TG2: 0.9995 | TH2: 0.9995 | TI2: 0.9995 | TJ2: 0.99916667 | TK2: 0.99916667 | TL2: 0.99883333 | TM2: 0.99883333 | TN2: 0.99833333 | TO2: 0.99816667 | TP2: 0.998 | TQ2: 0.998 | TR2: 0.998 | TS2: 0.998 | TT2: 0.998 | TU2: 0.99766667 | TV2: 0.99733333 | TW2: 0.99683333 | TX2: 0.99633333 | TY2: 0.99583333 | TZ2: 0.99516667 | UA2: 0.99466667 | UB2: 0.99433333 | UC2: 0.99366667 | UD2: 0.99316667 | UE2: 0.99266667 | UF2: 0.99216667 | UG2: 0.992 | UH2: 0.99133333 | UI2: 0.99 | UJ2: 0.98883333 | UK2: 0.9885 | UL2: 0.98833333 | UM2: 0.988 | UN2: 0.987 | UO2: 0.98616667 | UP2: 0.9855 | UQ2: 0.984 | UR2: 0.98266667 | US2: 0.98083333 | UT2: 0.97933333 | UU2: 0.9785 | UV2: 0.97683333 | UW2: 0.97533333 | UX2: 0.974 | UY2: 0.97133333 | UZ2: 0.96966667 | VA2: 0.96816667 | VB2: 0.96616667 | VC2: 0.96433333 | VD2: 0.962 | VE2: 0.96066667 | VF2: 0.95883333 | VG2: 0.9565 | VH2: 0.953 | VI2: 0.95083333 | VJ2: 0.94783333 | VK2: 0.94416667 | VL2: 0.94166667 | VM2: 0.93916667 | VN2: 0.93616667 | VO2: 0.93316667 | VP2: 0.9295 | VQ2: 0.92766667 | VR2: 0.92483333 | VS2: 0.92133333 | VT2: 0.9175 | VU2: 0.91283333 | VV2: 0.90783333 | VW2: 0.90416667 | VX2: 0.90016667 | VY2: 0.895 | VZ2: 0.89133333 | WA2: 0.88633333 | WB2: 0.88183333 | WC2: 0.87683333 | WD2: 0.87183333 | WE2: 0.8675 | WF2: 0.8615 | WG2: 0.856 | WH2: 0.85033333 | WI2: 0.84416667 | WJ2: 0.8395 | WK2: 0.83266667 | WL2: 0.82716667 | WM2: 0.822 | WN2: 0.81633333 | WO2: 0.8105 | WP2: 0.80283333 | WQ2: 0.79633333 | WR2: 0.78883333 | WS2: 0.78166667 | WT2: 0.774 | WU2: 0.7655 | WV2: 0.75783333 | WW2: 0.7505 | WX2: 0.74416667 | WY2: 0.73683333 | WZ2: 0.72833333 | XA2: 0.7215 | XB2: 0.71416667 | XC2: 0.70483333 | XD2: 0.6975 | XE2: 0.68783333 | XF2: 0.68 | XG2: 0.67266667 | XH2: 0.6655 | XI2: 0.65783333 | XJ2: 0.648 | XK2: 0.64033333 | XL2: 0.63016667 | XM2: 0.6235 | XN2: 0.61433333 | XO2: 0.6085 | XP2: 0.599 | XQ2: 0.59233333 | XR2: 0.5835 | XS2: 0.57683333 | XT2: 0.5685 | XU2: 0.55833333 | XV2: 0.55216667 | XW2: 0.54416667 | XX2: 0.53633333 | XY2: 0.528 | XZ2: 0.51833333 | YA2: 0.50766667 | YB2: 0.4995 | YC2: 0.49166667 | YD2: 0.485 | YE2: 0.47733333 | YF2: 0.47083333 | YG2: 0.46333333 | YH2: 0.45716667 | YI2: 0.45083333 | YJ2: 0.4445 | YK2: 0.4375 | YL2: 0.43016667 | YM2: 0.4225 | YN2: 0.41566667 | YO2: 0.40883333 | YP2: 0.40033333 | YQ2: 0.393 | YR2: 0.3865 | YS2: 0.38016667 | YT2: 0.37433333 | YU2: 0.36716667 | YV2: 0.3605 | YW2: 0.35416667 | YX2: 0.34783333 | YY2: 0.34166667 | YZ2: 0.334 | ZA2: 0.32783333 | ZB2: 0.3215 | ZC2: 0.3165 | ZD2: 0.31016667 | ZE2: 0.30283333 | ZF2: 0.29616667 | ZG2: 0.292 | ZH2: 0.28616667 | ZI2: 0.28083333 | ZJ2: 0.27533333 | ZK2: 0.26933333 | ZL2: 0.265 | ZM2: 0.26033333 | ZN2: 0.25583333 | ZO2: 0.25066667 | ZP2: 0.24716667 | ZQ2: 0.24166667 | ZR2: 0.23766667 | ZS2: 0.23333333 | ZT2: 0.2315 | ZU2: 0.225 | ZV2: 0.22183333 | ZW2: 0.2175 | ZX2: 0.21316667 | ZY2: 0.20833333 | ZZ2: 0.20233333 | AAA2: 0.19583333 | AAB2: 0.19233333 | AAC2: 0.18933333 | AAD2: 0.18566667 | AAE2: 0.18133333 | AAF2: 0.17766667 | AAG2: 0.174 | AAH2: 0.1705 | AAI2: 0.16683333 | AAJ2: 0.16433333 | AAK2: 0.1595 | AAL2: 0.15566667 | AAM2: 0.15333333 | AAN2: 0.14916667 | AAO2: 0.14616667 | AAP2: 0.142 | AAQ2: 0.138 | AAR2: 0.13533333 | AAS2: 0.13216667 | AAT2: 0.1295 | AAU2: 0.126 | AAV2: 0.1225 | AAW2: 0.1195 | AAX2: 0.1175 | AAY2: 0.11433333 | AAZ2: 0.112 | ABA2: 0.11016667 | ABB2: 0.1085 | ABC2: 0.107 | ABD2: 0.1045 | ABE2: 0.10266667 | ABF2: 0.10083333 | ABG2: 0.098666667 | ABH2: 0.0965 | ABI2: 0.0935 | ABJ2: 0.091833333 | ABK2: 0.089333333 | ABL2: 0.087666667 | ABM2: 0.085333333 | ABN2: 0.083333333 | ABO2: 0.081666667 | ABP2: 0.08 | ABQ2: 0.077833333 | ABR2: 0.075833333 | ABS2: 0.073666667 | ABT2: 0.072 | ABU2: 0.070833333 | ABV2: 0.068833333 | ABW2: 0.066166667 | ABX2: 0.064166667 | ABY2: 0.062833333 | ABZ2: 0.061833333 | ACA2: 0.060333333 | ACB2: 0.059166667 | ACC2: 0.058166667 | ACD2: 0.057333333 | ACE2: 0.056166667 | ACF2: 0.055166667 | ACG2: 0.0535 | ACH2: 0.053166667 | ACI2: 0.052 | ACJ2: 0.050166667 | ACK2: 0.0495 | ACL2: 0.0485 | ACM2: 0.047333333 | ACN2: 0.046333333 | ACO2: 0.045833333 | ACP2: 0.045 | ACQ2: 0.044333333 | ACR2: 0.042333333 | ACS2: 0.042 | ACT2: 0.041 | ACU2: 0.040166667 | ACV2: 0.04 | ACW2: 0.039166667 | ACX2: 0.037333333 | ACY2: 0.036833333 | ACZ2: 0.035333333 | ADA2: 0.034 | ADB2: 0.033166667 | ADC2: 0.032333333 | ADD2: 0.031666667 | ADE2: 0.031166667 | ADF2: 0.0305 | ADG2: 0.029833333 | ADH2: 0.029166667 | ADI2: 0.029 | ADJ2: 0.028 | ADK2: 0.027666667 | ADL2: 0.027166667 | ADM2: 0.027 | ADN2: 0.0265 | ADO2: 0.026166667 | ADP2: 0.025 | ADQ2: 0.024 | ADR2: 0.023833333 | ADS2: 0.022666667 | ADT2: 0.022 | ADU2: 0.021666667 | ADV2: 0.0205 | ADW2: 0.020166667 | ADX2: 0.019833333 | ADY2: 0.019333333 | ADZ2: 0.019166667 | AEA2: 0.018833333 | AEB2: 0.0185 | AEC2: 0.018333333 | AED2: 0.017666667 | AEE2: 0.017333333 | AEF2: 0.017 | AEG2: 0.016666667 | AEH2: 0.0165 | AEI2: 0.016166667 | AEJ2: 0.0155 | AEK2: 0.015 | AEL2: 0.015 | AEM2: 0.014666667 | AEN2: 0.014333333 | AEO2: 0.013833333 | AEP2: 0.013666667 | AEQ2: 0.013333333 | AER2: 0.012833333 | AES2: 0.012666667 | AET2: 0.0125 | AEU2: 0.012166667 | AEV2: 0.012166667 | AEW2: 0.012 | AEX2: 0.011333333 | AEY2: 0.011 | AEZ2: 0.0105 | AFA2: 0.010333333 | AFB2: 0.01 | AFC2: 0.01 | AFD2: 0.0096666667 | AFE2: 0.0093333333 | AFF2: 0.0093333333 | AFG2: 0.009 | AFH2: 0.009 | AFI2: 0.0088333333 | AFJ2: 0.0086666667 | AFK2: 0.0085 | AFL2: 0.0083333333 | AFM2: 0.0081666667 | AFN2: 0.0081666667 | AFO2: 0.0081666667 | AFP2: 0.0081666667 | AFQ2: 0.008 | AFR2: 0.008 | AFS2: 0.0078333333 | AFT2: 0.0075 | AFU2: 0.0075 | AFV2: 0.0071666667 | AFW2: 0.007 | AFX2: 0.007 | AFY2: 0.007 | AFZ2: 0.007 | AGA2: 0.0066666667 | AGB2: 0.0066666667 | AGC2: 0.0065 | AGD2: 0.0065 | AGE2: 0.0065 | AGF2: 0.0063333333 | AGG2: 0.0063333333 | AGH2: 0.0063333333 | AGI2: 0.0063333333 | AGJ2: 0.0061666667 | AGK2: 0.0061666667 | AGL2: 0.006 | AGM2: 0.0058333333 | AGN2: 0.0056666667 | AGO2: 0.0056666667 | AGP2: 0.0056666667 | AGQ2: 0.0055 | AGR2: 0.0053333333 | AGS2: 0.0051666667 | AGT2: 0.0051666667 | AGU2: 0.0051666667 | AGV2: 0.005 | AGW2: 0.005 | AGX2: 0.0048333333 | AGY2: 0.0046666667 | AGZ2: 0.0045 | AHA2: 0.0043333333 | AHB2: 0.0043333333 | AHC2: 0.0043333333 | AHD2: 0.0043333333 | AHE2: 0.0041666667 | AHF2: 0.004 | AHG2: 0.004 | AHH2: 0.004 | AHI2: 0.004 | AHJ2: 0.0036666667 | AHK2: 0.0035 | AHL2: 0.0033333333 | AHM2: 0.0031666667 | AHN2: 0.0031666667 | AHO2: 0.003 | AHP2: 0.0028333333 | AHQ2: 0.0028333333 | AHR2: 0.0028333333 | AHS2: 0.0028333333 | AHT2: 0.0028333333 | AHU2: 0.0028333333 | AHV2: 0.0028333333 | AHW2: 0.0026666667 | AHX2: 0.0026666667 | AHY2: 0.0025 | AHZ2: 0.0025 | AIA2: 0.0025 | AIB2: 0.0025 | AIC2: 0.0023333333 | AID2: 0.0021666667 | AIE2: 0.0021666667 | AIF2: 0.0021666667 | AIG2: 0.0021666667 | AIH2: 0.0021666667 | AII2: 0.0021666667 | AIJ2: 0.0018333333 | AIK2: 0.0018333333 | AIL2: 0.0018333333 | AIM2: 0.0018333333 | AIN2: 0.0016666667 | AIO2: 0.0016666667 | AIP2: 0.0016666667 | AIQ2: 0.0016666667 | AIR2: 0.0013333333 | AIS2: 0.0013333333 | AIT2: 0.0011666667 | AIU2: 0.0011666667 | AIV2: 0.0011666667 | AIW2: 0.0011666667 | AIX2: 0.0011666667 | AIY2: 0.0011666667 | AIZ2: 0.001 | AJA2: 0.00083333333 | AJB2: 0.00083333333 | AJC2: 0.00083333333 | AJD2: 0.00083333333 | AJE2: 0.00083333333 | AJF2: 0.00083333333 | AJG2: 0.00083333333 | AJH2: 0.00083333333 | AJI2: 0.00083333333 | AJJ2: 0.00083333333 | AJK2: 0.00083333333 | AJL2: 0.00083333333 | AJM2: 0.00083333333 | AJN2: 0.00083333333 | AJO2: 0.00083333333 | AJP2: 0.00083333333 | AJQ2: 0.00083333333 | AJR2: 0.00083333333 | AJS2: 0.00083333333 | AJT2: 0.00083333333 | AJU2: 0.00083333333 | AJV2: 0.00083333333 | AJW2: 0.00083333333 | AJX2: 0.00083333333 | AJY2: 0.00083333333 | AJZ2: 0.00083333333 | AKA2: 0.00083333333 | AKB2: 0.00066666667 | AKC2: 0.00066666667 | AKD2: 0.00066666667 | AKE2: 0.00066666667 | AKF2: 0.00066666667 | AKG2: 0.00066666667 | AKH2: 0.00066666667 | AKI2: 0.00066666667 | AKJ2: 0.00066666667 | AKK2: 0.00066666667 | AKL2: 0.00066666667 | AKM2: 0.00066666667 | AKN2: 0.00066666667 | AKO2: 0.00066666667 | AKP2: 0.00066666667 | AKQ2: 0.00066666667 | AKR2: 0.00066666667 | AKS2: 0.00066666667 | AKT2: 0.00066666667 | AKU2: 0.00066666667 | AKV2: 5e-04 | AKW2: 5e-04 | AKX2: 5e-04 | AKY2: 5e-04 | AKZ2: 5e-04 | ALA2: 0.00033333333 | ALB2: 0.00033333333 | ALC2: 0.00033333333 | ALD2: 0.00033333333 | ALE2: 0.00033333333 | ALF2: 0.00033333333 | ALG2: 0.00033333333 | ALH2: 0.00033333333 | ALI2: 0.00033333333 | ALJ2: 0.00033333333 | ALK2: 0.00033333333 | ALL2: 0.00033333333 | ALM2: 0.00033333333 | ALN2: 0.00016666667 | ALO2: 0.00016666667 | ALP2: 0.00016666667 | ALQ2: 0.00016666667 | ALR2: 0.00016666667 | ALS2: 0.00016666667 | ALT2: 0.00016666667 | ALU2: 0.00016666667 | ALV2: 0.00016666667 | ALW2: 0.00016666667 | ALX2: 0.00016666667 | ALY2: 0.00016666667 | ALZ2: 0.00016666667 | AMA2: 0.00016666667 | AMB2: 0.00016666667 | AMC2: 0 | AMD2: 0 | AME2: 0 | AMF2: 0 | AMG2: 0 | AMH2: 0 | AMI2: 0 | AMJ2: 0 | AMK2: 0 | AML2: 0 | AMM2: 0 | AMN2: 0 | AMO2: 0 | AMP2: 0 | AMQ2: 0 | AMR2: 0 | AMS2: 0 | AMT2: 0 | AMU2: 0 | AMV2: 0 | AMW2: 0 | AMX2: 0 | AMY2: 0 | AMZ2: 0 | ANA2: 0 | ANB2: 0 | ANC2: 0 | AND2: 0 | ANE2: 0 | ANF2: 0 | ANG2: 0 | ANH2: 0 | ANI2: 0 | ANJ2: 0 | ANK2: 0 | ANL2: 0 | ANM2: 0 | ANN2: 0 | ANO2: 0 | ANP2: 0 | ANQ2: 0 | ANR2: 0 | ANS2: 0 | ANT2: 0 | ANU2: 0 | ANV2: 0 | ANW2: 0 | ANX2: 0 | ANY2: 0 | ANZ2: 0 | AOA2: 0 | AOB2: 0 | AOC2: 0 | AOD2: 0 | AOE2: 0 | AOF2: 0 | AOG2: 0 | AOH2: 0 | AOI2: 0 | AOJ2: 0 | AOK2: 0 | AOL2: 0 | AOM2: 0 | AON2: 0 | AOO2: 0 | AOP2: 0 | AOQ2: 0 | AOR2: 0 | AOS2: 0 | AOT2: 0 | AOU2: 0 | AOV2: 0 | AOW2: 0 | AOX2: 0 | AOY2: 0 | AOZ2: 0 | APA2: 0 | APB2: 0 | APC2: 0 | APD2: 0 | APE2: 0 | APF2: 0 | APG2: 0 | APH2: 0 | API2: 0 | APJ2: 0 | APK2: 0 | APL2: 0 | APM2: 0 | APN2: 0 | APO2: 0 | APP2: 0 | APQ2: 0 | APR2: 0 | APS2: 0 | APT2: 0 | APU2: 0 | APV2: 0 | APW2: 0 | APX2: 0 | APY2: 0 | APZ2: 0 | AQA2: 0 | AQB2: 0 | AQC2: 0 | AQD2: 0 | AQE2: 0 | AQF2: 0 | AQG2: 0 | AQH2: 0 | AQI2: 0 | AQJ2: 0 | AQK2: 0 | AQL2: 0 | AQM2: 0 | AQN2: 0 | AQO2: 0 | AQP2: 0 | AQQ2: 0 | AQR2: 0 | AQS2: 0 | AQT2: 0 | AQU2: 0 | AQV2: 0 | AQW2: 0 | AQX2: 0 | AQY2: 0 | AQZ2: 0 | ARA2: 0 | ARB2: 0 | ARC2: 0 | ARD2: 0 | ARE2: 0 | ARF2: 0 | ARG2: 0 | ARH2: 0 | ARI2: 0 | ARJ2: 0 | ARK2: 0 | ARL2: 0 | ARM2: 0 | ARN2: 0 | ARO2: 0 | ARP2: 0 | ARQ2: 0 | ARR2: 0 | ARS2: 0 | ART2: 0 | ARU2: 0 | ARV2: 0 | ARW2: 0 | ARX2: 0 | ARY2: 0 | ARZ2: 0 | ASA2: 0 | ASB2: 0 | ASC2: 0 | ASD2: 0 | ASE2: 0 | ASF2: 0 | ASG2: 0 | ASH2: 0 | ASI2: 0 | ASJ2: 0 | ASK2: 0 | ASL2: 0 | ASM2: 0 | ASN2: 0 | ASO2: 0 | ASP2: 0 | ASQ2: 0 | ASR2: 0 | ASS2: 0 | AST2: 0 | ASU2: 0 | ASV2: 0 | ASW2: 0 | ASX2: 0 | ASY2: 0 | ASZ2: 0 | ATA2: 0 | ATB2: 0 | ATC2: 0 | ATD2: 0 | ATE2: 0 | ATF2: 0 | ATG2: 0 | ATH2: 0 | ATI2: 0 | ATJ2: 0 | ATK2: 0 | ATL2: 0 | ATM2: 0 | ATN2: 0 | ATO2: 0 | ATP2: 0 | ATQ2: 0 | ATR2: 0 | ATS2: 0 | ATT2: 0 | ATU2: 0 | ATV2: 0 | ATW2: 0 | ATX2: 0 | ATY2: 0 | ATZ2: 0 | AUA2: 0 | AUB2: 0 | AUC2: 0 | AUD2: 0 | AUE2: 0 | AUF2: 0 | AUG2: 0 | AUH2: 0 | AUI2: 0 | AUJ2: 0 | AUK2: 0 | AUL2: 0 | AUM2: 0 | AUN2: 0 | AUO2: 0 | AUP2: 0 | AUQ2: 0 | AUR2: 0 | AUS2: 0 | AUT2: 0 | AUU2: 0 | AUV2: 0 | AUW2: 0 | AUX2: 0 | AUY2: 0 | AUZ2: 0 | AVA2: 0 | AVB2: 0 | AVC2: 0 | AVD2: 0 | AVE2: 0 | AVF2: 0 | AVG2: 0 | AVH2: 0 | AVI2: 0 | AVJ2: 0 | AVK2: 0 | AVL2: 0 | AVM2: 0 | AVN2: 0 | AVO2: 0 | AVP2: 0 | AVQ2: 0 | AVR2: 0 | AVS2: 0 | AVT2: 0 | AVU2: 0 | AVV2: 0 | AVW2: 0 | AVX2: 0 | AVY2: 0 | AVZ2: 0 | AWA2: 0 | AWB2: 0 | AWC2: 0 | AWD2: 0 | AWE2: 0 | AWF2: 0 | AWG2: 0 | AWH2: 0 | AWI2: 0 | AWJ2: 0 | AWK2: 0 | AWL2: 0 | AWM2: 0 | AWN2: 0 | AWO2: 0 | AWP2: 0 | AWQ2: 0 | AWR2: 0 | AWS2: 0 | AWT2: 0 | AWU2: 0 | AWV2: 0 | AWW2: 0 | AWX2: 0 | AWY2: 0 | AWZ2: 0 | AXA2: 0 | AXB2: 0 | AXC2: 0 | AXD2: 0 | AXE2: 0 | AXF2: 0 | AXG2: 0 | AXH2: 0 | AXI2: 0 | AXJ2: 0 | AXK2: 0 | AXL2: 0 | AXM2: 0 | AXN2: 0 | AXO2: 0 | AXP2: 0 | AXQ2: 0 | AXR2: 0 | AXS2: 0 | AXT2: 0 | AXU2: 0 | AXV2: 0 | AXW2: 0 | AXX2: 0 | AXY2: 0 | AXZ2: 0 | AYA2: 0 | AYB2: 0 | AYC2: 0 | AYD2: 0 | AYE2: 0 | AYF2: 0 | AYG2: 0 | AYH2: 0 | AYI2: 0 | AYJ2: 0 | AYK2: 0 | AYL2: 0 | AYM2: 0 | AYN2: 0 | AYO2: 0 | AYP2: 0 | AYQ2: 0 | AYR2: 0 | AYS2: 0 | AYT2: 0 | AYU2: 0 | AYV2: 0 | AYW2: 0 | AYX2: 0 | AYY2: 0 | AYZ2: 0 | AZA2: 0 | AZB2: 0 | AZC2: 0 | AZD2: 0 | AZE2: 0 | AZF2: 0 | AZG2: 0 | AZH2: 0 | AZI2: 0 | AZJ2: 0 | AZK2: 0 | AZL2: 0 | AZM2: 0 | AZN2: 0 | AZO2: 0 | AZP2: 0 | AZQ2: 0 | AZR2: 0 | AZS2: 0 | AZT2: 0 | AZU2: 0 | AZV2: 0 | AZW2: 0 | AZX2: 0 | AZY2: 0 | AZZ2: 0 | BAA2: 0 | BAB2: 0 | BAC2: 0 | BAD2: 0 | BAE2: 0 | BAF2: 0 | BAG2: 0 | BAH2: 0 | BAI2: 0 | BAJ2: 0 | BAK2: 0 | BAL2: 0 | BAM2: 0 | BAN2: 0 | BAO2: 0 | BAP2: 0 | BAQ2: 0 | BAR2: 0 | BAS2: 0 | BAT2: 0 | BAU2: 0 | BAV2: 0 | BAW2: 0 | BAX2: 0 | BAY2: 0 | BAZ2: 0 | BBA2: 0 | BBB2: 0 | BBC2: 0 | BBD2: 0 | BBE2: 0 | BBF2: 0 | BBG2: 0 | BBH2: 0 | BBI2: 0 | BBJ2: 0 | BBK2: 0 | BBL2: 0 | BBM2: 0 | BBN2: 0 | BBO2: 0 | BBP2: 0 | BBQ2: 0 | BBR2: 0 | BBS2: 0 | BBT2: 0 | BBU2: 0 | BBV2: 0 | BBW2: 0 | BBX2: 0 | BBY2: 0 | BBZ2: 0 | BCA2: 0 | BCB2: 0 | BCC2: 0 | BCD2: 0 | BCE2: 0 | BCF2: 0 | BCG2: 0 | BCH2: 0 | BCI2: 0 | BCJ2: 0 | BCK2: 0 | BCL2: 0 | BCM2: 0 | BCN2: 0 | BCO2: 0 | BCP2: 0 | BCQ2: 0 | BCR2: 0 | BCS2: 0 | BCT2: 0 | BCU2: 0 | BCV2: 0 | BCW2: 0 | BCX2: 0 | BCY2: 0 | BCZ2: 0 | BDA2: 0 | BDB2: 0 | BDC2: 0 | BDD2: 0 | BDE2: 0 | BDF2: 0 | BDG2: 0 | BDH2: 0 | BDI2: 0 | BDJ2: 0 | BDK2: 0 | BDL2: 0 | BDM2: 0 | BDN2: 0 | BDO2: 0 | BDP2: 0 | BDQ2: 0 | BDR2: 0 | BDS2: 0 | BDT2: 0 | BDU2: 0 | BDV2: 0 | BDW2: 0 | BDX2: 0 | BDY2: 0 | BDZ2: 0 | BEA2: 0 | BEB2: 0 | BEC2: 0 | BED2: 0 | BEE2: 0 | BEF2: 0 | BEG2: 0 | BEH2: 0 | BEI2: 0 | BEJ2: 0 | BEK2: 0 | BEL2: 0 | BEM2: 0 | BEN2: 0 | BEO2: 0 | BEP2: 0 | BEQ2: 0 | BER2: 0 | BES2: 0 | BET2: 0 | BEU2: 0 | BEV2: 0 | BEW2: 0 | BEX2: 0 | BEY2: 0 | BEZ2: 0 | BFA2: 0 | BFB2: 0 | BFC2: 0 | BFD2: 0 | BFE2: 0 | BFF2: 0 | BFG2: 0 | BFH2: 0 | BFI2: 0 | BFJ2: 0 | BFK2: 0 | BFL2: 0 | BFM2: 0 | BFN2: 0 | BFO2: 0 | BFP2: 0 | BFQ2: 0 | BFR2: 0 | BFS2: 0 | BFT2: 0 | BFU2: 0 | BFV2: 0 | BFW2: 0 | BFX2: 0 | BFY2: 0 | BFZ2: 0 | BGA2: 0 | BGB2: 0 | BGC2: 0 | BGD2: 0 | BGE2: 0 | BGF2: 0 | BGG2: 0 | BGH2: 0 | BGI2: 0 | BGJ2: 0 | BGK2: 0 | BGL2: 0 | BGM2: 0 | BGN2: 0 | BGO2: 0 | BGP2: 0 | BGQ2: 0 | BGR2: 0 | BGS2: 0 | BGT2: 0 | BGU2: 0 | BGV2: 0 | BGW2: 0 | BGX2: 0 | BGY2: 0 | BGZ2: 0 | BHA2: 0 | BHB2: 0 | BHC2: 0 | BHD2: 0 | BHE2: 0 | BHF2: 0 | BHG2: 0 | BHH2: 0 | BHI2: 0 | BHJ2: 0 | BHK2: 0 | BHL2: 0 | BHM2: 0 | BHN2: 0 | BHO2: 0 | BHP2: 0 | BHQ2: 0 | BHR2: 0 | BHS2: 0 | BHT2: 0 | BHU2: 0 | BHV2: 0 | BHW2: 0 | BHX2: 0 | BHY2: 0 | BHZ2: 0 | BIA2: 0 | BIB2: 0 | BIC2: 0 | BID2: 0 | BIE2: 0 | BIF2: 0 | BIG2: 0 | BIH2: 0 | BII2: 0 | BIJ2: 0 | BIK2: 0 | BIL2: 0 | BIM2: 0 | BIN2: 0 | BIO2: 0 | BIP2: 0 | BIQ2: 0 | BIR2: 0 | BIS2: 0 | BIT2: 0 | BIU2: 0 | BIV2: 0 | BIW2: 0 | BIX2: 0 | BIY2: 0 | BIZ2: 0 | BJA2: 0 | BJB2: 0 | BJC2: 0 | BJD2: 0 | BJE2: 0 | BJF2: 0 | BJG2: 0 | BJH2: 0 | BJI2: 0 | BJJ2: 0 | BJK2: 0 | BJL2: 0 | BJM2: 0 | BJN2: 0 | BJO2: 0 | BJP2: 0 | BJQ2: 0 | BJR2: 0 | BJS2: 0 | BJT2: 0 | BJU2: 0 | BJV2: 0 | BJW2: 0 | BJX2: 0 | BJY2: 0 | BJZ2: 0 | BKA2: 0 | BKB2: 0 | BKC2: 0 | BKD2: 0 | BKE2: 0 | BKF2: 0 | BKG2: 0 | BKH2: 0 | BKI2: 0 | BKJ2: 0 | BKK2: 0 | BKL2: 0 | BKM2: 0 | BKN2: 0 | BKO2: 0 | BKP2: 0 | BKQ2: 0 | BKR2: 0 | BKS2: 0 | BKT2: 0 | BKU2: 0 | BKV2: 0 | BKW2: 0 | BKX2: 0 | BKY2: 0 | BKZ2: 0 | BLA2: 0 | BLB2: 0 | BLC2: 0 | BLD2: 0 | BLE2: 0 | BLF2: 0 | BLG2: 0 | BLH2: 0 | BLI2: 0 | BLJ2: 0 | BLK2: 0 | BLL2: 0 | BLM2: 0 | BLN2: 0 | BLO2: 0 | BLP2: 0 | BLQ2: 0 | BLR2: 0 | BLS2: 0 | BLT2: 0 | BLU2: 0 | BLV2: 0 | BLW2: 0 | BLX2: 0 | BLY2: 0 | BLZ2: 0 | BMA2: 0 | BMB2: 0 | BMC2: 0 | BMD2: 0 | BME2: 0 | BMF2: 0 | BMG2: 0 | BMH2: 0 | BMI2: 0 | BMJ2: 0 | BMK2: 0 | BML2: 0 | BMM2: 0 | BMN2: 0 | BMO2: 0 | BMP2: 0 | BMQ2: 0 | BMR2: 0 | BMS2: 0 | BMT2: 0 | BMU2: 0 | BMV2: 0 | BMW2: 0 | BMX2: 0 | BMY2: 0 | BMZ2: 0 | BNA2: 0 | BNB2: 0 | BNC2: 0 | BND2: 0 | BNE2: 0 | BNF2: 0 | BNG2: 0 | BNH2: 0 | BNI2: 0 | BNJ2: 0 | BNK2: 0 | BNL2: 0 | BNM2: 0 | BNN2: 0 | BNO2: 0 | BNP2: 0 | BNQ2: 0 | BNR2: 0 | BNS2: 0 | BNT2: 0 | BNU2: 0 | BNV2: 0 | BNW2: 0 | BNX2: 0 | BNY2: 0 | BNZ2: 0 | BOA2: 0 | BOB2: 0 | BOC2: 0 | BOD2: 0 | BOE2: 0 | BOF2: 0 | BOG2: 0 | BOH2: 0 | BOI2: 0 | BOJ2: 0 | BOK2: 0 | BOL2: 0 | BOM2: 0 | BON2: 0 | BOO2: 0 | BOP2: 0 | BOQ2: 0 | BOR2: 0 | BOS2: 0 | BOT2: 0 | BOU2: 0 | BOV2: 0 | BOW2: 0 | BOX2: 0 | BOY2: 0 | BOZ2: 0 | BPA2: 0 | BPB2: 0 | BPC2: 0 | BPD2: 0 | BPE2: 0 | BPF2: 0 | BPG2: 0 | BPH2: 0 | BPI2: 0 | BPJ2: 0 | BPK2: 0 | BPL2: 0 | BPM2: 0 | BPN2: 0 | BPO2: 0 | BPP2: 0 | BPQ2: 0 | BPR2: 0 | BPS2: 0 | BPT2: 0 | BPU2: 0 | BPV2: 0 | BPW2: 0 | BPX2: 0 | BPY2: 0 | BPZ2: 0 | BQA2: 0 | BQB2: 0 | BQC2: 0 | BQD2: 0 | BQE2: 0 | BQF2: 0 | BQG2: 0 | BQH2: 0 | BQI2: 0 | BQJ2: 0 | BQK2: 0 | BQL2: 0 | BQM2: 0 | BQN2: 0 | BQO2: 0 | BQP2: 0 | BQQ2: 0 | BQR2: 0 | BQS2: 0 | BQT2: 0 | BQU2: 0 | BQV2: 0 | BQW2: 0 | BQX2: 0 | BQY2: 0 | BQZ2: 0 | BRA2: 0 | BRB2: 0 | BRC2: 0 | BRD2: 0 | BRE2: 0 | BRF2: 0 | BRG2: 0 | BRH2: 0 | BRI2: 0 | BRJ2: 0 | BRK2: 0 | BRL2: 0 | BRM2: 0 | BRN2: 0 | BRO2: 0 | BRP2: 0 | BRQ2: 0 | BRR2: 0 | BRS2: 0 | BRT2: 0 | BRU2: 0 | BRV2: 0 | BRW2: 0 | BRX2: 0 | BRY2: 0 | BRZ2: 0 | BSA2: 0 | BSB2: 0 | BSC2: 0 | BSD2: 0 | BSE2: 0 | BSF2: 0 | BSG2: 0 | BSH2: 0 | BSI2: 0 | BSJ2: 0 | BSK2: 0 | BSL2: 0 | BSM2: 0 | BSN2: 0 | BSO2: 0 | BSP2: 0 | BSQ2: 0 | BSR2: 0 | BSS2: 0 | BST2: 0 | BSU2: 0 | BSV2: 0 | BSW2: 0 | BSX2: 0 | BSY2: 0 | BSZ2: 0 | BTA2: 0 | BTB2: 0 | BTC2: 0 | BTD2: 0 | BTE2: 0 | BTF2: 0 | BTG2: 0 | BTH2: 0 | BTI2: 0 | BTJ2: 0 | BTK2: 0 | BTL2: 0 | BTM2: 0 | BTN2: 0 | BTO2: 0 | BTP2: 0 | BTQ2: 0 | BTR2: 0 | BTS2: 0 | BTT2: 0 | BTU2: 0 | BTV2: 0 | BTW2: 0 | BTX2: 0 | BTY2: 0 | BTZ2: 0 | BUA2: 0 | BUB2: 0 | BUC2: 0 | BUD2: 0 | BUE2: 0 | BUF2: 0 | BUG2: 0 | BUH2: 0 | BUI2: 0 | BUJ2: 0 | BUK2: 0 | BUL2: 0 | BUM2: 0 | BUN2: 0 | BUO2: 0 | BUP2: 0 | BUQ2: 0 | BUR2: 0 | BUS2: 0 | BUT2: 0 | BUU2: 0 | BUV2: 0 | BUW2: 0 | BUX2: 0 | BUY2: 0 | BUZ2: 0 | BVA2: 0 | BVB2: 0 | BVC2: 0 | BVD2: 0 | BVE2: 0 | BVF2: 0 | BVG2: 0 | BVH2: 0 | BVI2: 0 | BVJ2: 0 | BVK2: 0 | BVL2: 0 | BVM2: 0 | BVN2: 0 | BVO2: 0 | BVP2: 0 | BVQ2: 0 | BVR2: 0 | BVS2: 0 | BVT2: 0 | BVU2: 0 | BVV2: 0 | BVW2: 0 | BVX2: 0 | BVY2: 0 | BVZ2: 0 | BWA2: 0 | BWB2: 0 | BWC2: 0 | BWD2: 0 | BWE2: 0 | BWF2: 0 | BWG2: 0 | BWH2: 0 | BWI2: 0 | BWJ2: 0 | BWK2: 0 | BWL2: 0 | BWM2: 0 | BWN2: 0 | BWO2: 0 | BWP2: 0 | BWQ2: 0 | BWR2: 0 | BWS2: 0 | BWT2: 0 | BWU2: 0 | BWV2: 0 | BWW2: 0 | BWX2: 0 | BWY2: 0 | BWZ2: 0 | BXA2: 0 | BXB2: 0 | BXC2: 0 | BXD2: 0 | BXE2: 0 | BXF2: 0 | BXG2: 0 | BXH2: 0 | BXI2: 0 | BXJ2: 0 | BXK2: 0 | BXL2: 0 | BXM2: 0 | BXN2: 0 | BXO2: 0 | BXP2: 0 | BXQ2: 0 | BXR2: 0 | BXS2: 0 | BXT2: 0 | BXU2: 0 | BXV2: 0 | BXW2: 0 | BXX2: 0 | BXY2: 0 | BXZ2: 0 | BYA2: 0 | BYB2: 0 | BYC2: 0 | BYD2: 0 | BYE2: 0 | BYF2: 0 | BYG2: 0 | BYH2: 0 | BYI2: 0 | BYJ2: 0 | BYK2: 0 | BYL2: 0 | BYM2: 0 | BYN2: 0 | BYO2: 0 | BYP2: 0 | BYQ2: 0 | BYR2: 0 | BYS2: 0 | BYT2: 0 | BYU2: 0 | BYV2: 0 | BYW2: 0 | BYX2: 0 | BYY2: 0 | BYZ2: 0 | BZA2: 0 | BZB2: 0 | BZC2: 0 | BZD2: 0 | BZE2: 0 | BZF2: 0 | BZG2: 0 | BZH2: 0 | BZI2: 0 | BZJ2: 0 | BZK2: 0 | BZL2: 0 | BZM2: 0 | BZN2: 0 | BZO2: 0 | BZP2: 0 | BZQ2: 0 | BZR2: 0 | BZS2: 0 | BZT2: 0 | BZU2: 0 | BZV2: 0 | BZW2: 0 | BZX2: 0 | BZY2: 0 | BZZ2: 0 | CAA2: 0 | CAB2: 0 | CAC2: 0 | CAD2: 0 | CAE2: 0 | CAF2: 0 | CAG2: 0 | CAH2: 0 | CAI2: 0 | CAJ2: 0 | CAK2: 0 | CAL2: 0 | CAM2: 0 | CAN2: 0 | CAO2: 0 | CAP2: 0 | CAQ2: 0 | CAR2: 0 | CAS2: 0 | CAT2: 0 | CAU2: 0 | CAV2: 0 | CAW2: 0 | CAX2: 0 | CAY2: 0 | CAZ2: 0 | CBA2: 0 | CBB2: 0 | CBC2: 0 | CBD2: 0 | CBE2: 0 | CBF2: 0 | CBG2: 0 | CBH2: 0 | CBI2: 0 | CBJ2: 0 | CBK2: 0 | CBL2: 0 | CBM2: 0 | CBN2: 0 | CBO2: 0 | CBP2: 0 | CBQ2: 0 | CBR2: 0 | CBS2: 0 | CBT2: 0 | CBU2: 0 | CBV2: 0 | CBW2: 0 | CBX2: 0 | CBY2: 0 | CBZ2: 0 | CCA2: 0 | CCB2: 0 | CCC2: 0 | CCD2: 0 | CCE2: 0 | CCF2: 0 | CCG2: 0 | CCH2: 0 | CCI2: 0 | CCJ2: 0 | CCK2: 0 | CCL2: 0 | CCM2: 0 | CCN2: 0 | CCO2: 0 | CCP2: 0 | CCQ2: 0 | CCR2: 0 | CCS2: 0 | CCT2: 0 | CCU2: 0 | CCV2: 0 | CCW2: 0 | CCX2: 0 | CCY2: 0 | CCZ2: 0 | CDA2: 0 | CDB2: 0 | CDC2: 0 | CDD2: 0 | CDE2: 0 | CDF2: 0 | CDG2: 0 | CDH2: 0 | CDI2: 0 | CDJ2: 0 | CDK2: 0 | CDL2: 0 | CDM2: 0 | CDN2: 0 | CDO2: 0 | CDP2: 0 | CDQ2: 0 | CDR2: 0 | CDS2: 0 | CDT2: 0 | CDU2: 0 | CDV2: 0 | CDW2: 0 | CDX2: 0 | CDY2: 0 | CDZ2: 0 | CEA2: 0 | CEB2: 0 | CEC2: 0 | CED2: 0 | CEE2: 0 | CEF2: 0 | CEG2: 0 | CEH2: 0 | CEI2: 0 | CEJ2: 0 | CEK2: 0 | CEL2: 0 | CEM2: 0 | CEN2: 0 | CEO2: 0 | CEP2: 0 | CEQ2: 0 | CER2: 0 | CES2: 0 | CET2: 0 | CEU2: 0 | CEV2: 0 | CEW2: 0 | CEX2: 0 | CEY2: 0 | CEZ2: 0 | CFA2: 0 | CFB2: 0 | CFC2: 0 | CFD2: 0 | CFE2: 0 | CFF2: 0 | CFG2: 0 | CFH2: 0 | CFI2: 0 | CFJ2: 0 | CFK2: 0 | CFL2: 0 | CFM2: 0 | CFN2: 0 | CFO2: 0 | CFP2: 0 | CFQ2: 0 | CFR2: 0 | CFS2: 0 | CFT2: 0 | CFU2: 0 | CFV2: 0 | CFW2: 0 | CFX2: 0 | CFY2: 0 | CFZ2: 0 | CGA2: 0 | CGB2: 0 | CGC2: 0 | CGD2: 0 | CGE2: 0 | CGF2: 0 | CGG2: 0 | CGH2: 0 | CGI2: 0 | CGJ2: 0 | CGK2: 0 | CGL2: 0 | CGM2: 0 | CGN2: 0 | CGO2: 0 | CGP2: 0 | CGQ2: 0 | CGR2: 0 | CGS2: 0 | CGT2: 0 | CGU2: 0 | CGV2: 0 | CGW2: 0 | CGX2: 0 | CGY2: 0 | CGZ2: 0 | CHA2: 0 | CHB2: 0 | CHC2: 0 | CHD2: 0 | CHE2: 0 | CHF2: 0 | CHG2: 0 | CHH2: 0 | CHI2: 0 | CHJ2: 0 | CHK2: 0 | CHL2: 0 | CHM2: 0 | CHN2: 0 | CHO2: 0 | CHP2: 0 | CHQ2: 0 | CHR2: 0 | CHS2: 0 | CHT2: 0 | CHU2: 0 | CHV2: 0 | CHW2: 0 | CHX2: 0 | CHY2: 0 | CHZ2: 0 | CIA2: 0 | CIB2: 0 | CIC2: 0 | CID2: 0 | CIE2: 0 | CIF2: 0 | CIG2: 0 | CIH2: 0 | CII2: 0 | CIJ2: 0 | CIK2: 0 | CIL2: 0 | CIM2: 0 | CIN2: 0 | CIO2: 0 | CIP2: 0 | CIQ2: 0 | CIR2: 0 | CIS2: 0 | CIT2: 0 | CIU2: 0 | CIV2: 0 | CIW2: 0 | CIX2: 0 | CIY2: 0 | CIZ2: 0 | CJA2: 0 | CJB2: 0 | CJC2: 0 | CJD2: 0 | CJE2: 0 | CJF2: 0 | CJG2: 0 | CJH2: 0 | CJI2: 0 | CJJ2: 0 | CJK2: 0 | CJL2: 0 | CJM2: 0 | CJN2: 0 | CJO2: 0 | CJP2: 0 | CJQ2: 0 | CJR2: 0 | CJS2: 0 | CJT2: 0 | CJU2: 0 | CJV2: 0 | CJW2: 0 | CJX2: 0 | CJY2: 0 | CJZ2: 0 | CKA2: 0 | CKB2: 0 | CKC2: 0 | CKD2: 0 | CKE2: 0 | CKF2: 0 | CKG2: 0 | CKH2: 0 | CKI2: 0 | CKJ2: 0 | CKK2: 0 | CKL2: 0 | CKM2: 0 | CKN2: 0 | CKO2: 0 | CKP2: 0 | CKQ2: 0 | CKR2: 0 | CKS2: 0 | CKT2: 0 | CKU2: 0 | CKV2: 0 | CKW2: 0 | CKX2: 0 | CKY2: 0 | CKZ2: 0 | CLA2: 0 | CLB2: 0 | CLC2: 0 | CLD2: 0 | CLE2: 0 | CLF2: 0 | CLG2: 0 | CLH2: 0 | CLI2: 0 | CLJ2: 0 | CLK2: 0 | CLL2: 0 | CLM2: 0 | CLN2: 0 | CLO2: 0 | CLP2: 0 | CLQ2: 0 | CLR2: 0 | CLS2: 0 | CLT2: 0 | CLU2: 0 | CLV2: 0 | CLW2: 0 | CLX2: 0 | CLY2: 0 | CLZ2: 0 | CMA2: 0 | CMB2: 0 | CMC2: 0 | CMD2: 0 | CME2: 0 | CMF2: 0 | CMG2: 0 | CMH2: 0 | CMI2: 0 | CMJ2: 0 | CMK2: 0 | CML2: 0 | CMM2: 0 | CMN2: 0 | CMO2: 0 | CMP2: 0 | CMQ2: 0 | CMR2: 0 | CMS2: 0 | CMT2: 0 | CMU2: 0 | CMV2: 0 | CMW2: 0 | CMX2: 0 | CMY2: 0 | CMZ2: 0 | CNA2: 0 | CNB2: 0 | CNC2: 0 | CND2: 0 | CNE2: 0 | CNF2: 0 | CNG2: 0 | CNH2: 0 | CNI2: 0 | CNJ2: 0 | CNK2: 0 | CNL2: 0 | CNM2: 0 | CNN2: 0 | CNO2: 0 | CNP2: 0 | CNQ2: 0 | CNR2: 0 | CNS2: 0 | CNT2: 0 | CNU2: 0 | CNV2: 0 | CNW2: 0 | CNX2: 0 | CNY2: 0 | CNZ2: 0 | COA2: 0 | COB2: 0 | COC2: 0 | COD2: 0 | COE2: 0 | COF2: 0 | COG2: 0 | COH2: 0 | COI2: 0 | COJ2: 0 | COK2: 0 | COL2: 0 | COM2: 0 | CON2: 0 | COO2: 0 | COP2: 0 | COQ2: 0 | COR2: 0 | COS2: 0 | COT2: 0 | COU2: 0 | COV2: 0 | COW2: 0 | COX2: 0 | COY2: 0 | COZ2: 0 | CPA2: 0 | CPB2: 0 | CPC2: 0 | CPD2: 0 | CPE2: 0 | CPF2: 0 | CPG2: 0 | CPH2: 0 | CPI2: 0 | CPJ2: 0 | CPK2: 0 | CPL2: 0 | CPM2: 0 | CPN2: 0 | CPO2: 0 | CPP2: 0 | CPQ2: 0 | CPR2: 0 | CPS2: 0 | CPT2: 0 | CPU2: 0 | CPV2: 0 | CPW2: 0 | CPX2: 0 | CPY2: 0 | CPZ2: 0 | CQA2: 0 | CQB2: 0 | CQC2: 0 | CQD2: 0 | CQE2: 0 | CQF2: 0 | CQG2: 0 | CQH2: 0 | CQI2: 0 | CQJ2: 0 | CQK2: 0 | CQL2: 0 | CQM2: 0 | CQN2: 0 | CQO2: 0 | CQP2: 0 | CQQ2: 0 | CQR2: 0 | CQS2: 0 | CQT2: 0 | CQU2: 0 | CQV2: 0 | CQW2: 0 | CQX2: 0 | CQY2: 0 | CQZ2: 0 | CRA2: 0 | CRB2: 0 | CRC2: 0 | CRD2: 0 | CRE2: 0 | CRF2: 0 | CRG2: 0 | CRH2: 0 | CRI2: 0 | CRJ2: 0 | CRK2: 0 | CRL2: 0 | CRM2: 0 | CRN2: 0 | CRO2: 0 | CRP2: 0 | CRQ2: 0 | CRR2: 0 | CRS2: 0 | CRT2: 0 | CRU2: 0 | CRV2: 0 | CRW2: 0 | CRX2: 0 | CRY2: 0 | CRZ2: 0 | CSA2: 0 | CSB2: 0 | CSC2: 0 | CSD2: 0 | CSE2: 0 | CSF2: 0 | CSG2: 0 | CSH2: 0 | CSI2: 0 | CSJ2: 0 | CSK2: 0 | CSL2: 0 | CSM2: 0 | CSN2: 0 | CSO2: 0 | CSP2: 0 | CSQ2: 0 | CSR2: 0 | CSS2: 0 | CST2: 0 | CSU2: 0 | CSV2: 0 | CSW2: 0 | CSX2: 0 | CSY2: 0 | CSZ2: 0 | CTA2: 0 | CTB2: 0 | CTC2: 0 | CTD2: 0 | CTE2: 0 | CTF2: 0 | CTG2: 0 | CTH2: 0 | CTI2: 0 | CTJ2: 0 | CTK2: 0 | CTL2: 0 | CTM2: 0 | CTN2: 0 | CTO2: 0 | CTP2: 0 | CTQ2: 0 | CTR2: 0 | CTS2: 0 | CTT2: 0 | CTU2: 0 | CTV2: 0 | CTW2: 0 | CTX2: 0 | CTY2: 0 | CTZ2: 0 | CUA2: 0 | CUB2: 0 | CUC2: 0 | CUD2: 0 | CUE2: 0 | CUF2: 0 | CUG2: 0 | CUH2: 0 | CUI2: 0 | CUJ2: 0 | CUK2: 0 | CUL2: 0 | CUM2: 0 | CUN2: 0 | CUO2: 0 | CUP2: 0 | CUQ2: 0 | CUR2: 0 | CUS2: 0 | CUT2: 0 | CUU2: 0 | CUV2: 0 | CUW2: 0 | CUX2: 0 | CUY2: 0 | CUZ2: 0 | CVA2: 0 | CVB2: 0 | CVC2: 0 | CVD2: 0 | CVE2: 0 | CVF2: 0 | CVG2: 0 | CVH2: 0 | CVI2: 0 | CVJ2: 0 | CVK2: 0 | CVL2: 0 | CVM2: 0 | CVN2: 0 | CVO2: 0 | CVP2: 0 | CVQ2: 0 | CVR2: 0 | CVS2: 0 | CVT2: 0 | CVU2: 0 | CVV2: 0 | CVW2: 0 | CVX2: 0 | CVY2: 0 | CVZ2: 0 | CWA2: 0 | CWB2: 0 | CWC2: 0 | CWD2: 0 | CWE2: 0 | CWF2: 0 | CWG2: 0 | CWH2: 0 | CWI2: 0 | CWJ2: 0 | CWK2: 0 | CWL2: 0 | CWM2: 0 | CWN2: 0 | CWO2: 0 | CWP2: 0 | CWQ2: 0 | CWR2: 0 | CWS2: 0 | CWT2: 0 | CWU2: 0 | CWV2: 0 | CWW2: 0 | CWX2: 0 | CWY2: 0 | CWZ2: 0 | CXA2: 0 | CXB2: 0 | CXC2: 0 | CXD2: 0 | CXE2: 0 | CXF2: 0 | CXG2: 0 | CXH2: 0 | CXI2: 0 | CXJ2: 0 | CXK2: 0 | CXL2: 0 | CXM2: 0 | CXN2: 0 | CXO2: 0 | CXP2: 0 | CXQ2: 0 | CXR2: 0 | CXS2: 0 | CXT2: 0 | CXU2: 0 | CXV2: 0 | CXW2: 0 | CXX2: 0 | CXY2: 0 | CXZ2: 0 | CYA2: 0 | CYB2: 0 | CYC2: 0 | CYD2: 0 | CYE2: 0 | CYF2: 0 | CYG2: 0 | CYH2: 0 | CYI2: 0 | CYJ2: 0 | CYK2: 0 | CYL2: 0 | CYM2: 0 | CYN2: 0 | CYO2: 0 | CYP2: 0 | CYQ2: 0 | CYR2: 0 | CYS2: 0 | CYT2: 0 | CYU2: 0 | CYV2: 0 | CYW2: 0 | CYX2: 0 | CYY2: 0 | CYZ2: 0 | CZA2: 0 | CZB2: 0 | CZC2: 0 | CZD2: 0 | CZE2: 0 | CZF2: 0 | CZG2: 0 | CZH2: 0 | CZI2: 0 | CZJ2: 0 | CZK2: 0 | CZL2: 0 | CZM2: 0 | CZN2: 0 | CZO2: 0 | CZP2: 0 | CZQ2: 0 | CZR2: 0 | CZS2: 0 | CZT2: 0 | CZU2: 0 | CZV2: 0 | CZW2: 0 | CZX2: 0 | CZY2: 0 | CZZ2: 0 | DAA2: 0 | DAB2: 0 | DAC2: 0 | DAD2: 0 | DAE2: 0 | DAF2: 0 | DAG2: 0 | DAH2: 0 | DAI2: 0 | DAJ2: 0 | DAK2: 0 | DAL2: 0 | DAM2: 0 | DAN2: 0 | DAO2: 0 | DAP2: 0 | DAQ2: 0 | DAR2: 0 | DAS2: 0 | DAT2: 0 | DAU2: 0 | DAV2: 0 | DAW2: 0 | DAX2: 0 | DAY2: 0 | DAZ2: 0 | DBA2: 0 | DBB2: 0 | DBC2: 0 | DBD2: 0 | DBE2: 0 | DBF2: 0 | DBG2: 0 | DBH2: 0 | DBI2: 0 | DBJ2: 0 | DBK2: 0 | DBL2: 0 | DBM2: 0 | DBN2: 0 | DBO2: 0 | DBP2: 0 | DBQ2: 0 | DBR2: 0 | DBS2: 0 | DBT2: 0 | DBU2: 0 | DBV2: 0 | DBW2: 0 | DBX2: 0 | DBY2: 0 | DBZ2: 0 | DCA2: 0 | DCB2: 0 | DCC2: 0 | DCD2: 0 | DCE2: 0 | DCF2: 0 | DCG2: 0 | DCH2: 0 | DCI2: 0 | DCJ2: 0 | DCK2: 0 | DCL2: 0 | DCM2: 0 | DCN2: 0 | DCO2: 0 | DCP2: 0 | DCQ2: 0 | DCR2: 0 | DCS2: 0 | DCT2: 0 | DCU2: 0 | DCV2: 0 | DCW2: 0 | DCX2: 0 | DCY2: 0 | DCZ2: 0 | DDA2: 0 | DDB2: 0 | DDC2: 0 | DDD2: 0 | DDE2: 0 | DDF2: 0 | DDG2: 0 | DDH2: 0 | DDI2: 0 | DDJ2: 0 | DDK2: 0 | DDL2: 0 | DDM2: 0 | DDN2: 0 | DDO2: 0 | DDP2: 0 | DDQ2: 0 | DDR2: 0 | DDS2: 0 | DDT2: 0 | DDU2: 0 | DDV2: 0 | DDW2: 0 | DDX2: 0 | DDY2: 0 | DDZ2: 0 | DEA2: 0 | DEB2: 0 | DEC2: 0 | DED2: 0 | DEE2: 0 | DEF2: 0 | DEG2: 0 | DEH2: 0 | DEI2: 0 | DEJ2: 0 | DEK2: 0 | DEL2: 0 | DEM2: 0 | DEN2: 0 | DEO2: 0 | DEP2: 0 | DEQ2: 0 | DER2: 0 | DES2: 0 | DET2: 0 | DEU2: 0 | DEV2: 0 | DEW2: 0 | DEX2: 0 | DEY2: 0 | DEZ2: 0 | DFA2: 0 | DFB2: 0 | DFC2: 0 | DFD2: 0 | DFE2: 0 | DFF2: 0 | DFG2: 0 | DFH2: 0 | DFI2: 0 | DFJ2: 0 | DFK2: 0 | DFL2: 0 | DFM2: 0 | DFN2: 0 | DFO2: 0 | DFP2: 0 | DFQ2: 0 | DFR2: 0 | DFS2: 0 | DFT2: 0 | DFU2: 0 | DFV2: 0 | DFW2: 0 | DFX2: 0 | DFY2: 0 | DFZ2: 0 | DGA2: 0 | DGB2: 0 | DGC2: 0 | DGD2: 0 | DGE2: 0 | DGF2: 0 | DGG2: 0 | DGH2: 0 | DGI2: 0 | DGJ2: 0 | DGK2: 0 | DGL2: 0 | DGM2: 0 | DGN2: 0 | DGO2: 0 | DGP2: 0 | DGQ2: 0 | DGR2: 0 | DGS2: 0 | DGT2: 0 | DGU2: 0 | DGV2: 0 | DGW2: 0 | DGX2: 0 | DGY2: 0 | DGZ2: 0 | DHA2: 0 | DHB2: 0 | DHC2: 0 | DHD2: 0 | DHE2: 0 | DHF2: 0 | DHG2: 0 | DHH2: 0 | DHI2: 0 | DHJ2: 0 | DHK2: 0 | DHL2: 0 | DHM2: 0 | DHN2: 0 | DHO2: 0 | DHP2: 0 | DHQ2: 0 | DHR2: 0 | DHS2: 0 | DHT2: 0 | DHU2: 0 | DHV2: 0 | DHW2: 0 | DHX2: 0 | DHY2: 0 | DHZ2: 0 | DIA2: 0 | DIB2: 0 | DIC2: 0 | DID2: 0 | DIE2: 0 | DIF2: 0 | DIG2: 0 | DIH2: 0 | DII2: 0 | DIJ2: 0 | DIK2: 0 | DIL2: 0 | DIM2: 0 | DIN2: 0 | DIO2: 0 | DIP2: 0 | DIQ2: 0 | DIR2: 0 | DIS2: 0 | DIT2: 0 | DIU2: 0 | DIV2: 0 | DIW2: 0 | DIX2: 0 | DIY2: 0 | DIZ2: 0 | DJA2: 0 | DJB2: 0 | DJC2: 0 | DJD2: 0 | DJE2: 0 | DJF2: 0 | DJG2: 0 | DJH2: 0 | DJI2: 0 | DJJ2: 0 | DJK2: 0 | DJL2: 0 | DJM2: 0 | DJN2: 0 | DJO2: 0 | DJP2: 0 | DJQ2: 0 | DJR2: 0 | DJS2: 0 | DJT2: 0 | DJU2: 0 | DJV2: 0 | DJW2: 0 | DJX2: 0 | DJY2: 0 | DJZ2: 0 | DKA2: 0 | DKB2: 0 | DKC2: 0 | DKD2: 0 | DKE2: 0 | DKF2: 0 | DKG2: 0 | DKH2: 0 | DKI2: 0 | DKJ2: 0 | DKK2: 0 | DKL2: 0 | DKM2: 0 | DKN2: 0 | DKO2: 0 | DKP2: 0 | DKQ2: 0 | DKR2: 0 | DKS2: 0 | DKT2: 0 | DKU2: 0 | DKV2: 0 | DKW2: 0 | DKX2: 0 | DKY2: 0 | DKZ2: 0 | DLA2: 0 | DLB2: 0 | DLC2: 0 | DLD2: 0 | DLE2: 0 | DLF2: 0 | DLG2: 0 | DLH2: 0 | DLI2: 0 | DLJ2: 0 | DLK2: 0 | DLL2: 0 | DLM2: 0 | DLN2: 0 | DLO2: 0 | DLP2: 0 | DLQ2: 0 | DLR2: 0 | DLS2: 0 | DLT2: 0 | DLU2: 0 | DLV2: 0 | DLW2: 0 | DLX2: 0 | DLY2: 0 | DLZ2: 0 | DMA2: 0 | DMB2: 0 | DMC2: 0 | DMD2: 0 | DME2: 0 | DMF2: 0 | DMG2: 0 | DMH2: 0 | DMI2: 0 | DMJ2: 0 | DMK2: 0 | DML2: 0 | DMM2: 0 | DMN2: 0 | DMO2: 0 | DMP2: 0 | DMQ2: 0 | DMR2: 0 | DMS2: 0 | DMT2: 0 | DMU2: 0 | DMV2: 0 | DMW2: 0 | DMX2: 0 | DMY2: 0 | DMZ2: 0 | DNA2: 0 | DNB2: 0 | DNC2: 0 | DND2: 0 | DNE2: 0 | DNF2: 0 | DNG2: 0 | DNH2: 0 | DNI2: 0 | DNJ2: 0 | DNK2: 0 | DNL2: 0 | DNM2: 0 | DNN2: 0 | DNO2: 0 | DNP2: 0 | DNQ2: 0 | DNR2: 0 | DNS2: 0 | DNT2: 0 | DNU2: 0 | DNV2: 0 | DNW2: 0 | DNX2: 0 | DNY2: 0 | DNZ2: 0 | DOA2: 0 | DOB2: 0 | DOC2: 0 | DOD2: 0 | DOE2: 0 | DOF2: 0 | DOG2: 0 | DOH2: 0 | DOI2: 0 | DOJ2: 0 | DOK2: 0 | DOL2: 0 | DOM2: 0 | DON2: 0 | DOO2: 0 | DOP2: 0 | DOQ2: 0 | DOR2: 0 | DOS2: 0 | DOT2: 0 | DOU2: 0 | DOV2: 0 | DOW2: 0 | DOX2: 0 | DOY2: 0 | DOZ2: 0 | DPA2: 0 | DPB2: 0 | DPC2: 0 | DPD2: 0 | DPE2: 0 | DPF2: 0 | DPG2: 0 | DPH2: 0 | DPI2: 0 | DPJ2: 0 | DPK2: 0 | DPL2: 0 | DPM2: 0 | DPN2: 0 | DPO2: 0 | DPP2: 0 | DPQ2: 0 | DPR2: 0 | DPS2: 0 | DPT2: 0 | DPU2: 0 | DPV2: 0 | DPW2: 0 | DPX2: 0 | DPY2: 0 | DPZ2: 0 | DQA2: 0 | DQB2: 0 | DQC2: 0 | DQD2: 0 | DQE2: 0 | DQF2: 0 | DQG2: 0 | DQH2: 0 | DQI2: 0 | DQJ2: 0 | DQK2: 0 | DQL2: 0 | DQM2: 0 | DQN2: 0 | DQO2: 0 | DQP2: 0 | DQQ2: 0 | DQR2: 0 | DQS2: 0 | DQT2: 0 | DQU2: 0 | DQV2: 0 | DQW2: 0 | DQX2: 0 | DQY2: 0 | DQZ2: 0 | DRA2: 0 | DRB2: 0 | DRC2: 0 | DRD2: 0 | DRE2: 0 | DRF2: 0 | DRG2: 0 | DRH2: 0 | DRI2: 0 | DRJ2: 0 | DRK2: 0 | DRL2: 0 | DRM2: 0 | DRN2: 0 | DRO2: 0 | DRP2: 0 | DRQ2: 0 | DRR2: 0 | DRS2: 0 | DRT2: 0 | DRU2: 0 | DRV2: 0 | DRW2: 0 | DRX2: 0 | DRY2: 0 | DRZ2: 0 | DSA2: 0 | DSB2: 0 | DSC2: 0 | DSD2: 0 | DSE2: 0 | DSF2: 0 | DSG2: 0 | DSH2: 0 | DSI2: 0 | DSJ2: 0 | DSK2: 0 | DSL2: 0 | DSM2: 0 | DSN2: 0 | DSO2: 0 | DSP2: 0 | DSQ2: 0 | DSR2: 0 | DSS2: 0 | DST2: 0 | DSU2: 0 | DSV2: 0 | DSW2: 0 | DSX2: 0 | DSY2: 0 | DSZ2: 0 | DTA2: 0 | DTB2: 0 | DTC2: 0 | DTD2: 0 | DTE2: 0 | DTF2: 0 | DTG2: 0 | DTH2: 0 | DTI2: 0 | DTJ2: 0 | DTK2: 0 | DTL2: 0 | DTM2: 0 | DTN2: 0 | DTO2: 0 | DTP2: 0 | DTQ2: 0 | DTR2: 0 | DTS2: 0 | DTT2: 0 | DTU2: 0 | DTV2: 0 | DTW2: 0 | DTX2: 0 | DTY2: 0 | DTZ2: 0 | DUA2: 0 | DUB2: 0 | DUC2: 0 | DUD2: 0 | DUE2: 0 | DUF2: 0 | DUG2: 0 | DUH2: 0 | DUI2: 0 | DUJ2: 0 | DUK2: 0 | DUL2: 0 | DUM2: 0 | DUN2: 0 | DUO2: 0 | DUP2: 0 | DUQ2: 0 | DUR2: 0 | DUS2: 0 | DUT2: 0 | DUU2: 0 | DUV2: 0 | DUW2: 0 | DUX2: 0 | DUY2: 0 | DUZ2: 0 | DVA2: 0 | DVB2: 0 | DVC2: 0 | DVD2: 0 | DVE2: 0 | DVF2: 0 | DVG2: 0 | DVH2: 0 | DVI2: 0 | DVJ2: 0 | DVK2: 0 | DVL2: 0 | DVM2: 0 | DVN2: 0 | DVO2: 0 | DVP2: 0 | DVQ2: 0 | DVR2: 0 | DVS2: 0 | DVT2: 0 | DVU2: 0 | DVV2: 0 | DVW2: 0 | DVX2: 0 | DVY2: 0 | DVZ2: 0 | DWA2: 0 | DWB2: 0 | DWC2: 0 | DWD2: 0 | DWE2: 0 | DWF2: 0 | DWG2: 0 | DWH2: 0 | DWI2: 0 | DWJ2: 0 | DWK2: 0 | DWL2: 0 | DWM2: 0 | DWN2: 0 | DWO2: 0 | DWP2: 0 | DWQ2: 0 | DWR2: 0 | DWS2: 0 | DWT2: 0 | DWU2: 0 | DWV2: 0 | DWW2: 0 | DWX2: 0 | DWY2: 0 | DWZ2: 0 | DXA2: 0 | DXB2: 0 | DXC2: 0 | DXD2: 0 | DXE2: 0 | DXF2: 0 | DXG2: 0 | DXH2: 0 | DXI2: 0 | DXJ2: 0 | DXK2: 0 | DXL2: 0 | DXM2: 0 | DXN2: 0 | DXO2: 0 | DXP2: 0 | DXQ2: 0 | DXR2: 0 | DXS2: 0 | DXT2: 0 | DXU2: 0 | DXV2: 0 | DXW2: 0 | DXX2: 0 | DXY2: 0 | DXZ2: 0 | DYA2: 0 | DYB2: 0 | DYC2: 0 | DYD2: 0 | DYE2: 0 | DYF2: 0 | DYG2: 0 | DYH2: 0 | DYI2: 0 | DYJ2: 0 | DYK2: 0 | DYL2: 0 | DYM2: 0 | DYN2: 0 | DYO2: 0 | DYP2: 0 | DYQ2: 0 | DYR2: 0 | DYS2: 0 | DYT2: 0 | DYU2: 0 | DYV2: 0 | DYW2: 0 | DYX2: 0 | DYY2: 0 | DYZ2: 0 | DZA2: 0 | DZB2: 0 | DZC2: 0 | DZD2: 0 | DZE2: 0 | DZF2: 0 | DZG2: 0 | DZH2: 0 | DZI2: 0 | DZJ2: 0 | DZK2: 0 | DZL2: 0 | DZM2: 0 | DZN2: 0 | DZO2: 0 | DZP2: 0 | DZQ2: 0 | DZR2: 0 | DZS2: 0 | DZT2: 0 | DZU2: 0 | DZV2: 0 | DZW2: 0 | DZX2: 0 | DZY2: 0 | DZZ2: 0 | EAA2: 0 | EAB2: 0 | EAC2: 0 | EAD2: 0 | EAE2: 0 | EAF2: 0 | EAG2: 0 | EAH2: 0 | EAI2: 0 | EAJ2: 0 | EAK2: 0 | EAL2: 0 | EAM2: 0 | EAN2: 0 | EAO2: 0 | EAP2: 0 | EAQ2: 0 | EAR2: 0 | EAS2: 0 | EAT2: 0 | EAU2: 0 | EAV2: 0 | EAW2: 0 | EAX2: 0 | EAY2: 0 | EAZ2: 0 | EBA2: 0 | EBB2: 0 | EBC2: 0 | EBD2: 0 | EBE2: 0 | EBF2: 0 | EBG2: 0 | EBH2: 0 | EBI2: 0 | EBJ2: 0 | EBK2: 0 | EBL2: 0 | EBM2: 0 | EBN2: 0 | EBO2: 0 | EBP2: 0 | EBQ2: 0 | EBR2: 0 | EBS2: 0 | EBT2: 0 | EBU2: 0 | EBV2: 0 | EBW2: 0 | EBX2: 0 | EBY2: 0 | EBZ2: 0 | ECA2: 0 | ECB2: 0 | ECC2: 0 | ECD2: 0 | ECE2: 0 | ECF2: 0 | ECG2: 0 | ECH2: 0 | ECI2: 0 | ECJ2: 0 | ECK2: 0 | ECL2: 0 | ECM2: 0 | ECN2: 0 | ECO2: 0 | ECP2: 0 | ECQ2: 0 | ECR2: 0 | ECS2: 0 | ECT2: 0 | ECU2: 0 | ECV2: 0 | ECW2: 0 | ECX2: 0 | ECY2: 0 | ECZ2: 0 | EDA2: 0 | EDB2: 0 | EDC2: 0 | EDD2: 0 | EDE2: 0 | EDF2: 0 | EDG2: 0 | EDH2: 0 | EDI2: 0 | EDJ2: 0 | EDK2: 0 | EDL2: 0 | EDM2: 0 | EDN2: 0 | EDO2: 0 | EDP2: 0 | EDQ2: 0 | EDR2: 0 | EDS2: 0 | EDT2: 0 | EDU2: 0 | EDV2: 0 | EDW2: 0 | EDX2: 0 | EDY2: 0 | EDZ2: 0 | EEA2: 0 | EEB2: 0 | EEC2: 0 | EED2: 0 | EEE2: 0 | EEF2: 0 | EEG2: 0 | EEH2: 0 | EEI2: 0 | EEJ2: 0 | EEK2: 0 | EEL2: 0 | EEM2: 0 | EEN2: 0 | EEO2: 0 | EEP2: 0 | EEQ2: 0 | EER2: 0 | EES2: 0 | EET2: 0 | EEU2: 0 | EEV2: 0 | EEW2: 0 | EEX2: 0 | EEY2: 0 | EEZ2: 0 | EFA2: 0 | EFB2: 0 | EFC2: 0 | EFD2: 0 | EFE2: 0 | EFF2: 0 | EFG2: 0 | EFH2: 0 | EFI2: 0 | EFJ2: 0 | EFK2: 0 | EFL2: 0 | EFM2: 0 | EFN2: 0 | EFO2: 0 | EFP2: 0 | EFQ2: 0 | EFR2: 0 | EFS2: 0 | EFT2: 0 | EFU2: 0 | EFV2: 0 | EFW2: 0 | EFX2: 0 | EFY2: 0 | EFZ2: 0 | EGA2: 0 | EGB2: 0 | EGC2: 0 | EGD2: 0 | EGE2: 0 | EGF2: 0 | EGG2: 0 | EGH2: 0 | EGI2: 0 | EGJ2: 0 | EGK2: 0 | EGL2: 0 | EGM2: 0 | EGN2: 0 | EGO2: 0 | EGP2: 0 | EGQ2: 0 | EGR2: 0 | EGS2: 0 | EGT2: 0 | EGU2: 0 | EGV2: 0 | EGW2: 0 | EGX2: 0 | EGY2: 0 | EGZ2: 0 | EHA2: 0 | EHB2: 0 | EHC2: 0 | EHD2: 0 | EHE2: 0 | EHF2: 0 | EHG2: 0 | EHH2: 0 | EHI2: 0 | EHJ2: 0 | EHK2: 0 | EHL2: 0 | EHM2: 0 | EHN2: 0 | EHO2: 0 | EHP2: 0 | EHQ2: 0 | EHR2: 0 | EHS2: 0 | EHT2: 0 | EHU2: 0 | EHV2: 0 | EHW2: 0 | EHX2: 0 | EHY2: 0 | EHZ2: 0 | EIA2: 0 | EIB2: 0 | EIC2: 0 | EID2: 0 | EIE2: 0 | EIF2: 0 | EIG2: 0 | EIH2: 0 | EII2: 0 | EIJ2: 0 | EIK2: 0 | EIL2: 0 | EIM2: 0 | EIN2: 0 | EIO2: 0 | EIP2: 0 | EIQ2: 0 | EIR2: 0 | EIS2: 0 | EIT2: 0 | EIU2: 0 | EIV2: 0 | EIW2: 0 | EIX2: 0 | EIY2: 0 | EIZ2: 0 | EJA2: 0 | EJB2: 0 | EJC2: 0 | EJD2: 0 | EJE2: 0 | EJF2: 0 | EJG2: 0 | EJH2: 0 | EJI2: 0 | EJJ2: 0 | EJK2: 0 | EJL2: 0 | EJM2: 0 | EJN2: 0 | EJO2: 0 | EJP2: 0 | EJQ2: 0 | EJR2: 0 | EJS2: 0 | EJT2: 0 | EJU2: 0 | EJV2: 0 | EJW2: 0 | EJX2: 0 | EJY2: 0 | EJZ2: 0 | EKA2: 0 | EKB2: 0 | EKC2: 0 | EKD2: 0 | EKE2: 0 | EKF2: 0 | EKG2: 0 | EKH2: 0 | EKI2: 0 | EKJ2: 0 | EKK2: 0 | EKL2: 0 | EKM2: 0 | EKN2: 0 | EKO2: 0 | EKP2: 0 | EKQ2: 0 | EKR2: 0 | EKS2: 0 | EKT2: 0 | EKU2: 0 | EKV2: 0 | EKW2: 0 | EKX2: 0 | EKY2: 0 | EKZ2: 0 | ELA2: 0 | ELB2: 0 | ELC2: 0 | ELD2: 0 | ELE2: 0 | ELF2: 0 | ELG2: 0 | ELH2: 0 | ELI2: 0 | ELJ2: 0 | ELK2: 0 | ELL2: 0 | ELM2: 0 | ELN2: 0 | ELO2: 0 | ELP2: 0 | ELQ2: 0 | ELR2: 0 | ELS2: 0 | ELT2: 0 | ELU2: 0 | ELV2: 0 | ELW2: 0 | ELX2: 0 | ELY2: 0 | ELZ2: 0 | EMA2: 0 | EMB2: 0 | EMC2: 0 | EMD2: 0 | EME2: 0 | EMF2: 0 | EMG2: 0 | EMH2: 0 | EMI2: 0 | EMJ2: 0 | EMK2: 0 | EML2: 0 | EMM2: 0 | EMN2: 0 | EMO2: 0 | EMP2: 0 | EMQ2: 0 | EMR2: 0 | EMS2: 0 | EMT2: 0 | EMU2: 0 | EMV2: 0 | EMW2: 0 | EMX2: 0 | EMY2: 0 | EMZ2: 0 | ENA2: 0 | ENB2: 0 | ENC2: 0 | END2: 0 | ENE2: 0 | ENF2: 0 | ENG2: 0 | ENH2: 0 | ENI2: 0 | ENJ2: 0 | ENK2: 0 | ENL2: 0 | ENM2: 0 | ENN2: 0 | ENO2: 0 | ENP2: 0 | ENQ2: 0 | ENR2: 0 | ENS2: 0 | ENT2: 0 | ENU2: 0 | ENV2: 0 | ENW2: 0 | ENX2: 0 | ENY2: 0 | ENZ2: 0 | EOA2: 0 | EOB2: 0 | EOC2: 0 | EOD2: 0 | EOE2: 0 | EOF2: 0 | EOG2: 0 | EOH2: 0 | EOI2: 0 | EOJ2: 0 | EOK2: 0 | EOL2: 0 | EOM2: 0 | EON2: 0 | EOO2: 0 | EOP2: 0 | EOQ2: 0 | EOR2: 0 | EOS2: 0 | EOT2: 0 | EOU2: 0 | EOV2: 0 | EOW2: 0 | EOX2: 0 | EOY2: 0 | EOZ2: 0 | EPA2: 0 | EPB2: 0 | EPC2: 0 | EPD2: 0 | EPE2: 0 | EPF2: 0 | EPG2: 0 | EPH2: 0 | EPI2: 0 | EPJ2: 0 | EPK2: 0 | EPL2: 0 | EPM2: 0 | EPN2: 0 | EPO2: 0 | EPP2: 0 | EPQ2: 0 | EPR2: 0 | EPS2: 0 | EPT2: 0 | EPU2: 0 | EPV2: 0 | EPW2: 0 | EPX2: 0 | EPY2: 0 | EPZ2: 0 | EQA2: 0 | EQB2: 0 | EQC2: 0 | EQD2: 0 | EQE2: 0 | EQF2: 0 | EQG2: 0 | EQH2: 0 | EQI2: 0 | EQJ2: 0 | EQK2: 0 | EQL2: 0 | EQM2: 0 | EQN2: 0 | EQO2: 0 | EQP2: 0 | EQQ2: 0 | EQR2: 0 | EQS2: 0 | EQT2: 0 | EQU2: 0 | EQV2: 0 | EQW2: 0 | EQX2: 0 | EQY2: 0 | EQZ2: 0 | ERA2: 0 | ERB2: 0 | ERC2: 0 | ERD2: 0 | ERE2: 0 | ERF2: 0 | ERG2: 0 | ERH2: 0 | ERI2: 0 | ERJ2: 0 | ERK2: 0 | ERL2: 0 | ERM2: 0 | ERN2: 0 | ERO2: 0 | ERP2: 0 | ERQ2: 0 | ERR2: 0 | ERS2: 0 | ERT2: 0 | ERU2: 0 | ERV2: 0 | ERW2: 0 | ERX2: 0 | ERY2: 0 | ERZ2: 0 | ESA2: 0 | ESB2: 0 | ESC2: 0 | ESD2: 0 | ESE2: 0 | ESF2: 0 | ESG2: 0 | ESH2: 0 | ESI2: 0 | ESJ2: 0 | ESK2: 0 | ESL2: 0 | ESM2: 0 | ESN2: 0 | ESO2: 0 | ESP2: 0 | ESQ2: 0 | ESR2: 0 | ESS2: 0 | EST2: 0 | ESU2: 0 | ESV2: 0 | ESW2: 0 | ESX2: 0 | ESY2: 0 | ESZ2: 0 | ETA2: 0 | ETB2: 0 | ETC2: 0 | ETD2: 0 | ETE2: 0 | ETF2: 0 | ETG2: 0 | ETH2: 0 | ETI2: 0 | ETJ2: 0 | ETK2: 0 | ETL2: 0 | ETM2: 0 | ETN2: 0 | ETO2: 0 | ETP2: 0 | ETQ2: 0 | ETR2: 0 | ETS2: 0 | ETT2: 0 | ETU2: 0 | ETV2: 0 | ETW2: 0 | ETX2: 0 | ETY2: 0 | ETZ2: 0 | EUA2: 0 | EUB2: 0 | EUC2: 0 | EUD2: 0 | EUE2: 0 | EUF2: 0 | EUG2: 0 | EUH2: 0 | EUI2: 0 | EUJ2: 0 | EUK2: 0 | EUL2: 0 | EUM2: 0 | EUN2: 0 | EUO2: 0 | EUP2: 0 | EUQ2: 0 | EUR2: 0 | EUS2: 0 | EUT2: 0 | EUU2: 0 | EUV2: 0 | EUW2: 0 | EUX2: 0 | EUY2: 0 | EUZ2: 0 | EVA2: 0 | EVB2: 0 | EVC2: 0 | EVD2: 0 | EVE2: 0 | EVF2: 0 | EVG2: 0 | EVH2: 0 | EVI2: 0 | EVJ2: 0 | EVK2: 0 | EVL2: 0 | EVM2: 0 | EVN2: 0 | EVO2: 0 | EVP2: 0 | EVQ2: 0 | EVR2: 0 | EVS2: 0 | EVT2: 0 | EVU2: 0 | EVV2: 0 | EVW2: 0 | EVX2: 0 | EVY2: 0 | EVZ2: 0 | EWA2: 0 | EWB2: 0 | EWC2: 0 | EWD2: 0 | EWE2: 0 | EWF2: 0 | EWG2: 0 | EWH2: 0 | EWI2: 0 | EWJ2: 0 | EWK2: 0 | EWL2: 0 | EWM2: 0 | EWN2: 0 | EWO2: 0 | EWP2: 0 | EWQ2: 0 | EWR2: 0 | EWS2: 0 | EWT2: 0 | EWU2: 0 | EWV2: 0 | EWW2: 0 | EWX2: 0 | EWY2: 0
